Workbook
Name x: #N/A

Sheet Summary
A1: BRDB LAND — FEASIBILITY STUDY SUMMARY | Named Ranges Registry
A2: All values RM | Col D (live values) reads directly via named ranges | Col F = ExcelJS getValue() path for Nuxt dashboard
A3: Feasibility Study | B3: Named Range | C3: Cell Ref | D3: Live Value | E3: Description | F3: Nuxt ExcelJS path
A6: 2 | B6: DevLandArea_Acres | C6: ='Feasibility Study'!#REF! -> #REF! | D6: =DevLandArea_Acres -> #NAME? | E6: Total dev land (acres) | F6: summary.devLandAcres
A7: 3 | B7: TotalPhasesLandArea_Acres | C7: ='Feasibility Study'!AY10 -> 0
A8: 4 | B8: TotalPhasesLandArea_Sqft | C8: ='Feasibility Study'!AY12 -> 0
A9: 5 | B9: TotalUnits_AllPhases | C9: ='Feasibility Study'!AY13 -> 0 | D9: =TotalUnits_AllPhases -> #NAME? | E9: Total units — all phases | F9: summary.totalUnits | AY9: Phase 3a
A10: 6 | B10: TotalNFA_AllPhases_Sqft | C10: ='Feasibility Study'!AY17 -> 0 | D10: =TotalNFA_AllPhases_Sqft -> #NAME? | E10: Total NFA — all phases (sqft) | F10: summary.totalNFASqft
A11: 7 | B11: TotalGFA_ExcludeCP_Sqft | C11: ='Feasibility Study'!AY16 -> 0 | D11: =TotalGFA_ExcludeCP_Sqft -> #NAME? | E11: Total GFA excl carpark (sqft) | F11: summary.totalGFASqft
A12: GDV WATERFALL
A13: 8 | B13: GDV_Total | C13: ='Feasibility Study'!AY69 | D13: =GDV_Total -> #NAME? | E13: Gross Development Value (RM) | F13: gdv.total
A14: 9 | B14: GDV_GrossSellingPSF | C14: ='Feasibility Study'!AY70 | D14: =GDV_GrossSellingPSF -> #NAME? | E14: GDV gross selling price psf (RM) | F14: gdv.grossPSF
A15: 10 | B15: BumiDiscount_Total | C15: ='Feasibility Study'!AY72 -> 0 | D15: =BumiDiscount_Total -> #NAME? | E15: Less: Bumiputera Discount (RM) | F15: gdv.bumiDiscount
A16: 11 | B16: BumiPenalty_Total | C16: ='Feasibility Study'!AY73 -> 0 | D16: =BumiPenalty_Total -> #NAME? | E16: Less: Bumiputera Penalty (RM) | F16: gdv.bumiPenalty
A17: 12 | B17: LegalFeesSelling_Total | C17: ='Feasibility Study'!AY74 -> 0 | D17: =LegalFeesSelling_Total -> #NAME? | E17: Less: Legal fees SPA (RM) | F17: gdv.legalFees
A18: 13 | B18: EarlyBirdDiscount_Total | C18: ='Feasibility Study'!AY75 | D18: =EarlyBirdDiscount_Total -> #NAME? | E18: Less: Early Bird Discount 9% (RM) | F18: gdv.earlyBird
A19: 14 | B19: NDV_Total | C19: ='Feasibility Study'!AY79 | D19: =NDV_Total -> #NAME? | E19: Net Development Value (RM) | F19: ndv.total
A20: 15 | B20: NDV_NetSellingPSF | C20: ='Feasibility Study'!AY83 -> #DIV/0! | D20: =NDV_NetSellingPSF -> #NAME? | E20: NDV net selling price psf (RM) | F20: ndv.netPSF
A21: LAND & RELATED COSTS
A22: 16 | B22: LandRelatedCosts_Total | C22: ='Feasibility Study'!AY87 -> #DIV/0! | D22: =LandRelatedCosts_Total -> #NAME? | E22: Sec 5 — Land & related total (RM) | F22: gdc.land.total
A23: 17 | B23: LandCost_Total | C23: ='Feasibility Study'!AY88 -> 0 | D23: =LandCost_Total -> #NAME? | E23: 5.1 Land cost (RM) | F23: gdc.land.landCost
A24: 18 | B24: LandConversionPremium_Total | C24: ='Feasibility Study'!AY89 -> 0 | D24: =LandConversionPremium_Total -> #NAME? | E24: 5.2 Land conversion premium (RM) | F24: gdc.land.conversionPremium
A25: 19 | B25: QuitRent_Total | C25: ='Feasibility Study'!AY90 -> 0 | D25: =QuitRent_Total -> #NAME? | E25: 5.3 Quit rent (RM) | F25: gdc.land.quitRent
A26: 20 | B26: Assessment_Total | C26: ='Feasibility Study'!AY91 -> 0 | D26: =Assessment_Total -> #NAME? | E26: 5.4 Assessment (RM) | F26: gdc.land.assessment
A27: 21 | B27: StampDuty_Total | C27: ='Feasibility Study'!AY92 -> #DIV/0! | D27: =StampDuty_Total -> #NAME? | E27: 5.5 Stamp duty on land (RM) | F27: gdc.land.stampDuty
A28: 22 | B28: ValuationFee_Total | C28: ='Feasibility Study'!AY94 -> 0 | D28: =ValuationFee_Total -> #NAME? | E28: 5.6 Valuation fee (RM) | F28: gdc.land.valuation
A29: 23 | B29: LandAmalgamation_Total | C29: ='Feasibility Study'!AY95 -> 0 | D29: =LandAmalgamation_Total -> #NAME? | E29: 5.7 Land amalgamation fee (RM) | F29: gdc.land.amalgamation
A30: GROSS CONSTRUCTION COST (GCC)
A31: 24 | B31: GCC_Total | C31: ='Feasibility Study'!AY99 -> #DIV/0! | D31: =GCC_Total -> #NAME? | E31: Sec 6 — GCC total (RM) | F31: gdc.gcc.total
A32: 25 | B32: GCC_PercentOfNDV | C32: ='Feasibility Study'!AY100 -> #DIV/0! | D32: =GCC_PercentOfNDV -> #NAME? | E32: GCC % of NDV | F32: gdc.gcc.pctOfNDV
A33: 26 | B33: GCC_ConstructionCostPSF | C33: ='Feasibility Study'!AY101 -> #DIV/0! | D33: =GCC_ConstructionCostPSF -> #NAME? | E33: GCC construction cost psf (RM) | F33: gdc.gcc.costPSF
A34: 27 | B34: SubstructurePiling_Total | C34: ='Feasibility Study'!AY102 -> 0 | D34: =SubstructurePiling_Total -> #NAME? | E34: Piling / substructure (RM) | F34: gdc.gcc.piling
A35: 28 | B35: BuildingWork_Resi_Total | C35: ='Feasibility Study'!AY105 -> #DIV/0! | D35: =BuildingWork_Resi_Total -> #NAME? | E35: Building works resi (RM) | F35: gdc.gcc.buildingResi
A36: 29 | B36: BuildingWork_Afford_Total | C36: ='Feasibility Study'!AY106 -> 0 | D36: =BuildingWork_Afford_Total -> #NAME? | E36: Building works affordable (RM) | F36: gdc.gcc.buildingAfford
A37: 30 | B37: BuildingWork_Comm_Total | C37: ='Feasibility Study'!AY107 -> 0 | D37: =BuildingWork_Comm_Total -> #NAME? | E37: Building works commercial (RM) | F37: gdc.gcc.buildingComm
A38: 31 | B38: KitchenCabinet_Total | C38: ='Feasibility Study'!AY109 -> #VALUE! | D38: =KitchenCabinet_Total -> #NAME? | E38: Kitchen cabinet & appliances (RM) | F38: gdc.gcc.kitchenCabinet
A39: 32 | B39: IDWorks_Unit_Total | C39: ='Feasibility Study'!AY110 -> #VALUE! | D39: =IDWorks_Unit_Total -> #NAME? | E39: ID works — unit fit-out (RM) | F39: gdc.gcc.idWorks
A40: 33 | B40: Earthworks_Total | C40: ='Feasibility Study'!AY131 -> #VALUE! | D40: =Earthworks_Total -> #NAME? | E40: Earthworks & infrastructure (RM) | F40: gdc.gcc.earthworks
A41: 34 | B41: Landscape_Total | C41: ='Feasibility Study'!AY133 -> 0 | D41: =Landscape_Total -> #NAME? | E41: Landscape (RM) | F41: gdc.gcc.landscape
A42: 35 | B42: Clubhouse_Total | C42: ='Feasibility Study'!AY135 -> #DIV/0! | D42: =Clubhouse_Total -> #NAME? | E42: Clubhouse / show units (RM) | F42: gdc.gcc.clubhouse
...

Sheet Feasibility Study
A1: BRDB LAND
A2: OVERALL FEASIBILITY STUDY
A3: Feasibility Study
AW4: Phase 2j
G5: Acre to Sqm | H5: 4046.87
G6: Acre to Sqft | H6: 43560 | I6: Phase 1a | K6: Phase 1b | M6: Phase 1c | O6: Phase 1d | Q6: Phase 1e | S6: Phase 1f | W6: Phase 1g | Y6: Phase 1h | AC6: Phase 2a | AE6: Phase 2B | AG6: Phase 2c | AI6: Phase 2d | AK6: Phase 2e | AM6: Phase 2f | AO6: Phase 2g1 | AQ6: Phase 2g2 | AS6: Phase 2g3 | AU6: Phase 2h
A8: LAUNCH DATE | I8: 42095 | K8: 42401 | M8: 45017 | O8: TBC | Q8: TBC | S8: 46631 | W8: 46935 | Y8: 11171 | AC8: 44044 | AE8: 44835 | AG8: 45931 | AI8: 46419 | AK8: 46419 | AM8: TBC | AO8: TBC | AQ8: TBC | AS8: TBC | AU8: TBC | AW8: TBC | AY8: TOTAL
C10: Phases Land Area (acres) => | I10: 0 | K10: 0 | M10: 0 | O10: 0 | Q10: 0 | S10: 0 | W10: 0 | Y10: 0 | AC10: 0 | AE10: 0 | AG10: 0 | AI10: 0 | AK10: 0 | AM10: 0 | AO10: 0 | AQ10: 0 | AS10: 0 | AU10: 0 | AW10: 0 | AY10: =SUM(I10:AW10) -> 0
C11: Phases Land Area (square meter) => | I11: =I10*$H$5 -> 0 | K11: =K10*$H$5 -> 0 | M11: =M10*$H$5 -> 0 | O11: =O10*$H$5 -> 0 | Q11: =Q10*$H$5 -> 0 | S11: 0 | W11: =W10*$H$5 -> 0 | Y11: =Y10*$H$5 -> 0 | AC11: =AC10*$H$5 -> 0 | AE11: =AE10*$H$5 -> 0 | AG11: =AG10*$H$5 -> 0 | AI11: =AI10*$H$5 -> 0 | AK11: =AK10*$H$5 -> 0 | AM11: =AM10*$H$5 -> 0 | AO11: =AO10*$H$5 -> 0 | AQ11: =AQ10*$H$5 -> 0 | AS11: =AS10*$H$5 -> 0 | AU11: =AU10*$H$5 -> 0 | AW11: =AW10*$H$5 -> 0 | AY11: =SUM(I11:AW11) -> 0
C12: Phases Land Area (square feet) => | I12: =I10*$H$6 -> 0 | K12: =K10*$H$6 -> 0 | M12: =M10*$H$6 -> 0 | O12: =O10*$H$6 -> 0 | Q12: =Q10*$H$6 -> 0 | S12: =S10*$H$6 -> 0 | W12: =W10*$H$6 -> 0 | Y12: =Y10*$H$6 -> 0 | AC12: =AC10*$H$6 -> 0 | AE12: =AE10*$H$6 -> 0 | AG12: =AG10*$H$6 -> 0 | AI12: =AI10*$H$6 -> 0 | AK12: =AK10*$H$6 -> 0 | AM12: =AM10*$H$6 -> 0 | AO12: =AO10*$H$6 -> 0 | AQ12: =AQ10*$H$6 -> 0 | AS12: =AS10*$H$6 -> 0 | AU12: =AU10*$H$6 -> 0 | AW12: =AW10*$H$6 -> 0 | AY12: =SUM(I12:AW12) -> 0
C13: No of units in the Phase => | I13: =E31 -> 0 | K13: =E44 -> 0 | M13: =E45 -> 0 | O13: =E46 -> 0 | Q13: 0 | S13: =E49+E50 -> 0 | W13: =E51 -> 0 | Y13: =E52 -> 0 | AC13: =E53 -> 0 | AE13: =E54 -> 0 | AG13: =E55 -> 0 | AI13: =E56 -> 0 | AK13: =E57 -> 0 | AM13: =E58 -> 0 | AO13: =E59 -> 0 | AQ13: =E60 -> 0 | AS13: 0 | AU13: =E62 -> 0 | AW13: =E63 -> 0 | AY13: =SUM(I13:AW13) -> 0
C14: Carpark Bays (Required — authority minimum) => | I14: 0
C15: Construction Floor Area include Carpark (CFA) =>
C16: Gross Floor Area exclude Carpark (GFA) =>
C17: Saleable area in the Phase (NFA) => | I17: 0 | K17: =K13*D44 -> 0 | M17: =M13*D45 -> 0 | O17: =O13*D46 -> 0 | Q17: =Q13*D47 -> 0 | S17: =(E49*D49)+(D50*E50) -> 0 | W17: =W13*D51 -> 0 | Y17: =Y13*D52 -> 0 | AC17: =AC13*D53 -> 0 | AE17: =AE13*D54 -> 0 | AG17: =AG13*D55 -> 0 | AI17: =AI13*D56 -> 0 | AK17: =AK13*D57 -> 0 | AM17: =AM13*D58 -> 0 | AO17: =AO13*D59 -> 0 | AQ17: =AQ13*D60 -> 0 | AS17: =AS13*D61 -> 0 | AU17: =AU13*D62 -> 0 | AW17: =AW13*D63 -> 0 | AY17: =SUM(I17:AW17) -> 0
C18: Highrise Design Efficiency (NSA ÷ CFA) =>
C19: Highrise Design Efficiency (NSA ÷ GFA) =>
C20: Plot Ratio / Density =>
I21: 0 | K21: 0 | M21: 0 | O21: 0 | Q21: 0 | S21: 0 | W21: 0 | Y21: 0 | AC21: 0 | AE21: 0 | AG21: 0 | AI21: 0 | AK21: 0 | AM21: 0 | AO21: 0 | AQ21: 0 | AS21: 0 | AU21: 0 | AW21: 0 | AY21: =SUM(I21:AW21) -> 0
I22: 0 | K22: 0 | M22: 0 | O22: 0 | Q22: 0 | S22: 0 | W22: 0 | Y22: 0 | AC22: 0 | AE22: 0 | AG22: 0 | AI22: 0 | AK22: 0 | AM22: 0 | AO22: 0 | AQ22: 0 | AS22: 0 | AU22: 0 | AW22: 0 | AY22: =SUM(I22:AW22) -> 0
I23: =IFERROR(I17/I22,0) -> 0 | K23: =IFERROR(K17/K22,0) -> 0 | M23: =IFERROR(M17/M22,0) -> 0 | O23: =IFERROR(O17/O22,0) -> 0 | Q23: =IFERROR(Q17/Q22,0) -> 0 | S23: =IFERROR(S17/S22,0) -> 0 | W23: =IFERROR(W17/W22,0) -> 0 | Y23: =IFERROR(Y17/Y22,0) -> 0 | AC23: =IFERROR(AC17/AC22,0) -> 0 | AE23: =IFERROR(AE17/AE22,0) -> 0 | AG23: =IFERROR(AG17/AG22,0) -> 0 | AI23: =IFERROR(AI17/AI22,0) -> 0 | AK23: =IFERROR(AK17/AK22,0) -> 0 | AM23: =IFERROR(AM17/AM22,0) -> 0 | AO23: =IFERROR(AO17/AO22,0) -> 0 | AQ23: =IFERROR(AQ17/AQ22,0) -> 0 | AS23: =IFERROR(AS17/AS22,0) -> 0 | AU23: =IFERROR(AU17/AU22,0) -> 0 | AW23: =IFERROR(AW17/AW22,0) -> 0 | AY23: =IFERROR(AY17/AY22,0) -> 0
I24: 0 | K24: 0 | M24: 0 | O24: 0 | Q24: 0 | S24: 0 | W24: 0 | Y24: 0 | AC24: 0 | AE24: 0 | AG24: 0 | AI24: 0 | AK24: 0 | AM24: 0 | AO24: 0 | AQ24: 0 | AS24: 0 | AU24: 0 | AW24: 0 | AY24: =SUM(I24:AW24) -> 0
I25: =IF(I10=0,0,I13/I10) -> 0 | K25: =K13/K10 -> #DIV/0! | M25: =M13/M10 -> #DIV/0! | O25: =O13/O10 -> #DIV/0! | Q25: =Q17/Q12 -> #DIV/0! | S25: =S17/S12 -> #DIV/0! | W25: =W17/W12 -> #DIV/0! | Y25: =Y17/Y12 -> #DIV/0! | AC25: =AC13/AC10 -> #DIV/0! | AE25: =AE13/AE10 -> #DIV/0! | AG25: =AG13/AG10 -> #DIV/0! | AI25: =AI13/AI10 -> #DIV/0! | AK25: =AK13/AK10 -> #DIV/0! | AM25: =AM13/AM10 -> #DIV/0! | AO25: =AO13/AO10 -> #DIV/0! | AQ25: =AQ13/AQ10 -> #DIV/0! | AS25: =AS13/AS10 -> #DIV/0! | AU25: =AU13/AU10 -> #DIV/0! | AW25: =AW17/AW12 -> #DIV/0!
A26: A | B26: GROSS DEVELOPMENT VALUE
S27: Mixed Comm | W27: Mixed Comm | Y27: Mixed Comm
A28: 1 | B28: Type of Development | D28: Mixed Development | I28: 3 Sty Superlink | K28: 3 Sty Superlink | M28: Affordable Home | O28: Affordable Home | Q28: Commercial | S28: S. Apartment | W28: S.Apartment | Y28: S.Apartment | AC28: 2 Sty Linkhouse | AE28: 2 Sty Linkhouse | AG28: 2 Sty Linkhouse | AI28: 2 Sty Semi-D | AK28: 2 Sty Semi-D | AM28: Zero Lot Bungalow | AO28: Condominium | AQ28: Condominium | AS28: Recreational | AU28: Terrace House | AW28: Commercial Shoplot
A29: =A24+1 -> 1 | B29: Total No of Units | C29: a) Residential | D29: =E31+E45+E46+E53+E54+E55+E56+E57+E58+E60+E59+E62 -> 0 | Q29: Shop-lot | S29: Retail Shoplots | W29: Retail Shoplots | Y29: Retail Shoplots | AO29: High Rise | AQ29: High Rise | AS29: Park
C30: b) Commercial | D30: =E47+E48+E51+E52+E63+E61 -> 0
A31: =A25+1 -> 1 | B31: Total Saleable Area (NFA) | C31: a) Residential | D31: =I17+K17+M17+O17+AC17+AE17+AG17+AI17+AK17+AU17+AM17+AO17+AQ17 -> 0
C32: b) Commercial | D32: =Q17+S17+W17+Y17+AW17+AS17 -> 0
A33: =A27+1 -> 1 | B33: Net Selling Price psf | C33: a) Residential | D33: =IFERROR((I73+K73+M73+O73+AC73+AE73+AG73+AI73+AU73)/D27,0) | E33: b) Commercial | F33: =IFERROR((Q73+S73+W73+Y73+AW73)/D28,0) | I33: =IFERROR(I73/I17,0) | K33: =IFERROR(K73/K17,0) | M33: =IFERROR(M73/M17,0) | O33: =IFERROR(O73/O17,0) | Q33: =IFERROR(Q73/Q17,0) | S33: =IFERROR(S73/S17,0) | W33: =IFERROR(W73/W17,0) | Y33: =IFERROR(Y73/Y17,0) | AC33: =IFERROR(AC73/AC17,0) | AE33: =IFERROR(AE73/AE17,0) | AG33: =IFERROR(AG73/AG17,0) | AI33: =IFERROR(AI73/AI17,0) | AK33: =IFERROR(AK73/AK17,0) | AM33: =IFERROR(AM73/AM17,0) | AO33: =IFERROR(AO73/AO17,0) | AQ33: =IFERROR(AQ73/AQ17,0) | AS33: =IFERROR(AS73/AS17,0) | AU33: =IFERROR(AU73/AU17,0) | AW33: =IFERROR(AW73/AW17,0)
D34: Unit Avg size | E34: Units | F34: RM'psf Nett (NSA) | G34: Average Price/unit (Nett)
C35: Ph 1a - 3 Storey Superlinks | D35: 1500 | E35: 0 | F35: 0 | G35: =F31*D31 -> 0 | I35: =G31*E31/2 -> 0 | K35: =G44*E44/2 -> 0 | AY35: =SUM(I31:AW31) -> 0
C36: Superlink (24' x 65')Intermediate | D36: 2586 | F36: 290.2091 | G36: 320.966 | AY36: =SUM(I32:AW32) -> 0
C37: Superlink (24' x 65') Corner | D37: 2605 | F37: 322.4 | G37: 359.499 | AY37: =SUM(I33:AW33)
C38: Superlink (26' x 65') Intermediate | D38: 2864 | F38: 285.67 | G38: 314.384 | AY38: =SUM(I34:AW34) -> 0
C39: Superlink (26' x 65')Corner | D39: 3150 | F39: 310.32 | G39: 335.33 | AY39: =SUM(I35:AW35) -> 0
C40: Superlink (30' x 65') Intermediate | D40: 3527 | F40: 263.39 | G40: 305.177 | AY40: =SUM(I36:AW36) -> 0
C41: Superlink (30' x 65') Corner | D41: 3510 | F41: 287.12 | G41: 331.815 | AY41: =SUM(I37:AW37) -> 0
C42: Superlink (24' x 70') Intermediate | D42: 2586 | F42: 289.29 | G42: 320.966 | AY42: =SUM(I38:AW38) -> 0
...

Sheet Cashflow
A1: BRDB LAND — MONTHLY CASHFLOW MODEL (RM'000)
A2: All values RM'000 | Blue = inputs | Black = formulas | Green = linked from Feasibility Study
C3: Year 1 | O3: Year 2 | AA3: Year 3 | AM3: Year 4 | AY3: Year 5
A4: DESCRIPTION | B4: BASIS / TOTAL (RM'000) | C4: Jan '26 | D4: Feb '26 | E4: Mar '26 | F4: Apr '26 | G4: May '26 | H4: Jun '26 | I4: Jul '26 | J4: Aug '26 | K4: Sep '26 | L4: Oct '26 | M4: Nov '26 | N4: Dec '26 | O4: Jan '27 | P4: Feb '27 | Q4: Mar '27 | R4: Apr '27 | S4: May '27 | T4: Jun '27 | U4: Jul '27 | V4: Aug '27 | W4: Sep '27 | X4: Oct '27 | Y4: Nov '27 | Z4: Dec '27 | AA4: Jan '28 | AB4: Feb '28 | AC4: Mar '28 | AD4: Apr '28 | AE4: May '28 | AF4: Jun '28 | AG4: Jul '28 | AH4: Aug '28 | AI4: Sep '28 | AJ4: Oct '28 | AK4: Nov '28 | AL4: Dec '28 | AM4: Jan '29 | AN4: Feb '29 | AO4: Mar '29 | AP4: Apr '29 | AQ4: May '29 | AR4: Jun '29 | AS4: Jul '29 | AT4: Aug '29 | AU4: Sep '29 | AV4: Oct '29 | AW4: Nov '29 | AX4: Dec '29 | AY4: Jan '30 | AZ4: Feb '30 | BA4: Mar '30 | BB4: Apr '30 | BC4: May '30 | BD4: Jun '30 | BE4: Jul '30 | BF4: Aug '30 | BG4: Sep '30 | BH4: Oct '30 | BI4: Nov '30 | BJ4: Dec '30 | BK4: TOTAL
A5: Start date | C5: 46023 | D5: 46054 | E5: 46082 | F5: 46113 | G5: 46143 | H5: 46174 | I5: 46204 | J5: 46235 | K5: 46266 | L5: 46296 | M5: 46327 | N5: 46357 | O5: 46388 | P5: 46419 | Q5: 46447 | R5: 46478 | S5: 46508 | T5: 46539 | U5: 46569 | V5: 46600 | W5: 46631 | X5: 46661 | Y5: 46692 | Z5: 46722 | AA5: 46753 | AB5: 46784 | AC5: 46813 | AD5: 46844 | AE5: 46874 | AF5: 46905 | AG5: 46935 | AH5: 46966 | AI5: 46997 | AJ5: 47027 | AK5: 47058 | AL5: 47088 | AM5: 47119 | AN5: 47150 | AO5: 47178 | AP5: 47209 | AQ5: 47239 | AR5: 47270 | AS5: 47300 | AT5: 47331 | AU5: 47362 | AV5: 47392 | AW5: 47423 | AX5: 47453 | AY5: 47484 | AZ5: 47515 | BA5: 47543 | BB5: 47574 | BC5: 47604 | BD5: 47635 | BE5: 47665 | BF5: 47696 | BG5: 47727 | BH5: 47757 | BI5: 47788 | BJ5: 47818
A7: A. PROJECT ASSUMPTIONS
A8: Project name | B8: BRDB Land Development
A9: Development period (years) | B9: 5
A10: Project start | B10: January 2026
A11: Total GDV (RM'000) | B11: ='Feasibility Study'!AY65/1000
A12: Total NDV (RM'000) | B12: ='Feasibility Study'!AY73/1000 -> 0
A13: Total GDC (RM'000) | B13: ='Feasibility Study'!AY157/1000 -> 0
A14: Total NDP (RM'000) | B14: ='Feasibility Study'!AY170/1000 -> 0
A15: Land cost (RM'000) | B15: ='Feasibility Study'!AY82/1000 -> 0
A16: Construction cost (RM'000) | B16: ='Feasibility Study'!AY87/1000 -> #DIV/0!
A17: Annual interest rate | B17: 0.0455
A18: Target IRR (hurdle) | B18: 0.16
A20: B. MONTHLY SALES ABSORPTION SCHEDULE (% of NDV collected per month)
A21: S-curve absorption — slow launch M1–M6, peak Y2–Y3, tail-off Y4–Y5. Edit % in blue.
A22: Phase | B22: Type | C22: Jan | D22: Feb | E22: Mar | F22: Apr | G22: May | H22: Jun | I22: Jul | J22: Aug | K22: Sep | L22: Oct | M22: Nov | N22: Dec | O22: Jan | P22: Feb | Q22: Mar | R22: Apr | S22: May | T22: Jun | U22: Jul | V22: Aug | W22: Sep | X22: Oct | Y22: Nov | Z22: Dec | AA22: Jan | AB22: Feb | AC22: Mar | AD22: Apr | AE22: May | AF22: Jun | AG22: Jul | AH22: Aug | AI22: Sep | AJ22: Oct | AK22: Nov | AL22: Dec | AM22: Jan | AN22: Feb | AO22: Mar | AP22: Apr | AQ22: May | AR22: Jun | AS22: Jul | AT22: Aug | AU22: Sep | AV22: Oct | AW22: Nov | AX22: Dec | AY22: Jan | AZ22: Feb | BA22: Mar | BB22: Apr | BC22: May | BD22: Jun | BE22: Jul | BF22: Aug | BG22: Sep | BH22: Oct | BI22: Nov | BJ22: Dec | BK22: Total %
A23: Ph 1a | B23: residential | C23: 0.01 | D23: 0.01 | E23: 0.01 | F23: 0.02 | G23: 0.02 | H23: 0.02 | I23: 0.02 | J23: 0.02 | K23: 0.02 | L23: 0.03 | M23: 0.03 | N23: 0.03 | O23: 0.03 | P23: 0.03 | Q23: 0.03 | R23: 0.04 | S23: 0.04 | T23: 0.04 | U23: 0.04 | V23: 0.04 | W23: 0.04 | X23: 0.04 | Y23: 0.03 | Z23: 0.03 | AA23: 0.03 | AB23: 0.03 | AC23: 0.03 | AD23: 0.02 | AE23: 0.02 | AF23: 0.02 | AG23: 0.02 | AH23: 0.02 | AI23: 0.02 | AJ23: 0.02 | AK23: 0.02 | AL23: 0.02 | AM23: 0.01 | AN23: 0.01 | AO23: 0.01 | AP23: 0.01 | AQ23: 0.01 | AR23: 0.01 | AS23: 0 | AT23: 0 | AU23: 0 | AV23: 0 | AW23: 0 | AX23: 0 | AY23: 0 | AZ23: 0 | BA23: 0 | BB23: 0 | BC23: 0 | BD23: 0 | BE23: 0 | BF23: 0 | BG23: 0 | BH23: 0 | BI23: 0 | BJ23: 0 | BK23: =SUM(C23:BJ23) -> 1
A24: Ph 1b | B24: residential | C24: 0.01 | D24: 0.01 | E24: 0.01 | F24: 0.02 | G24: 0.02 | H24: 0.02 | I24: 0.02 | J24: 0.02 | K24: 0.02 | L24: 0.03 | M24: 0.03 | N24: 0.03 | O24: 0.03 | P24: 0.03 | Q24: 0.03 | R24: 0.04 | S24: 0.04 | T24: 0.04 | U24: 0.04 | V24: 0.04 | W24: 0.04 | X24: 0.04 | Y24: 0.03 | Z24: 0.03 | AA24: 0.03 | AB24: 0.03 | AC24: 0.03 | AD24: 0.02 | AE24: 0.02 | AF24: 0.02 | AG24: 0.02 | AH24: 0.02 | AI24: 0.02 | AJ24: 0.02 | AK24: 0.02 | AL24: 0.02 | AM24: 0.01 | AN24: 0.01 | AO24: 0.01 | AP24: 0.01 | AQ24: 0.01 | AR24: 0.01 | AS24: 0 | AT24: 0 | AU24: 0 | AV24: 0 | AW24: 0 | AX24: 0 | AY24: 0 | AZ24: 0 | BA24: 0 | BB24: 0 | BC24: 0 | BD24: 0 | BE24: 0 | BF24: 0 | BG24: 0 | BH24: 0 | BI24: 0 | BJ24: 0 | BK24: =SUM(C24:BJ24) -> 1
A25: Ph 1c | B25: affordable | C25: 0.02 | D25: 0.02 | E25: 0.03 | F25: 0.03 | G25: 0.03 | H25: 0.05 | I25: 0.04 | J25: 0.04 | K25: 0.04 | L25: 0.04 | M25: 0.04 | N25: 0.04 | O25: 0.04 | P25: 0.04 | Q25: 0.04 | R25: 0.04 | S25: 0.03 | T25: 0.03 | U25: 0.03 | V25: 0.03 | W25: 0.03 | X25: 0.03 | Y25: 0.03 | Z25: 0.03 | AA25: 0.02 | AB25: 0.02 | AC25: 0.02 | AD25: 0.02 | AE25: 0.02 | AF25: 0.02 | AG25: 0.01 | AH25: 0.01 | AI25: 0.01 | AJ25: 0.01 | AK25: 0.01 | AL25: 0.01 | AM25: 0 | AN25: 0 | AO25: 0 | AP25: 0 | AQ25: 0 | AR25: 0 | AS25: 0 | AT25: 0 | AU25: 0 | AV25: 0 | AW25: 0 | AX25: 0 | AY25: 0 | AZ25: 0 | BA25: 0 | BB25: 0 | BC25: 0 | BD25: 0 | BE25: 0 | BF25: 0 | BG25: 0 | BH25: 0 | BI25: 0 | BJ25: 0 | BK25: =SUM(C25:BJ25) -> 1
A26: Ph 1d | B26: affordable | C26: 0.02 | D26: 0.02 | E26: 0.03 | F26: 0.03 | G26: 0.03 | H26: 0.05 | I26: 0.04 | J26: 0.04 | K26: 0.04 | L26: 0.04 | M26: 0.04 | N26: 0.04 | O26: 0.04 | P26: 0.04 | Q26: 0.04 | R26: 0.04 | S26: 0.03 | T26: 0.03 | U26: 0.03 | V26: 0.03 | W26: 0.03 | X26: 0.03 | Y26: 0.03 | Z26: 0.03 | AA26: 0.02 | AB26: 0.02 | AC26: 0.02 | AD26: 0.02 | AE26: 0.02 | AF26: 0.02 | AG26: 0.01 | AH26: 0.01 | AI26: 0.01 | AJ26: 0.01 | AK26: 0.01 | AL26: 0.01 | AM26: 0 | AN26: 0 | AO26: 0 | AP26: 0 | AQ26: 0 | AR26: 0 | AS26: 0 | AT26: 0 | AU26: 0 | AV26: 0 | AW26: 0 | AX26: 0 | AY26: 0 | AZ26: 0 | BA26: 0 | BB26: 0 | BC26: 0 | BD26: 0 | BE26: 0 | BF26: 0 | BG26: 0 | BH26: 0 | BI26: 0 | BJ26: 0 | BK26: =SUM(C26:BJ26) -> 1
A27: Ph 1e | B27: commercial | C27: 0.02 | D27: 0.03 | E27: 0.03 | F27: 0.04 | G27: 0.04 | H27: 0.04 | I27: 0.04 | J27: 0.04 | K27: 0.05 | L27: 0.05 | M27: 0.05 | N27: 0.05 | O27: 0.05 | P27: 0.05 | Q27: 0.05 | R27: 0.05 | S27: 0.04 | T27: 0.04 | U27: 0.04 | V27: 0.04 | W27: 0.03 | X27: 0.03 | Y27: 0.02 | Z27: 0.02 | AA27: 0.01 | AB27: 0.01 | AC27: 0.01 | AD27: 0.01 | AE27: 0.01 | AF27: 0.01 | AG27: 0 | AH27: 0 | AI27: 0 | AJ27: 0 | AK27: 0 | AL27: 0 | AM27: 0 | AN27: 0 | AO27: 0 | AP27: 0 | AQ27: 0 | AR27: 0 | AS27: 0 | AT27: 0 | AU27: 0 | AV27: 0 | AW27: 0 | AX27: 0 | AY27: 0 | AZ27: 0 | BA27: 0 | BB27: 0 | BC27: 0 | BD27: 0 | BE27: 0 | BF27: 0 | BG27: 0 | BH27: 0 | BI27: 0 | BJ27: 0 | BK27: =SUM(C27:BJ27) -> 1
A28: Ph 1f | B28: residential | C28: 0.01 | D28: 0.01 | E28: 0.01 | F28: 0.02 | G28: 0.02 | H28: 0.02 | I28: 0.02 | J28: 0.02 | K28: 0.02 | L28: 0.03 | M28: 0.03 | N28: 0.03 | O28: 0.03 | P28: 0.03 | Q28: 0.03 | R28: 0.04 | S28: 0.04 | T28: 0.04 | U28: 0.04 | V28: 0.04 | W28: 0.04 | X28: 0.04 | Y28: 0.03 | Z28: 0.03 | AA28: 0.03 | AB28: 0.03 | AC28: 0.03 | AD28: 0.02 | AE28: 0.02 | AF28: 0.02 | AG28: 0.02 | AH28: 0.02 | AI28: 0.02 | AJ28: 0.02 | AK28: 0.02 | AL28: 0.02 | AM28: 0.01 | AN28: 0.01 | AO28: 0.01 | AP28: 0.01 | AQ28: 0.01 | AR28: 0.01 | AS28: 0 | AT28: 0 | AU28: 0 | AV28: 0 | AW28: 0 | AX28: 0 | AY28: 0 | AZ28: 0 | BA28: 0 | BB28: 0 | BC28: 0 | BD28: 0 | BE28: 0 | BF28: 0 | BG28: 0 | BH28: 0 | BI28: 0 | BJ28: 0 | BK28: =SUM(C28:BJ28) -> 1
A29: Ph 1g | B29: commercial | C29: 0.02 | D29: 0.03 | E29: 0.03 | F29: 0.04 | G29: 0.04 | H29: 0.04 | I29: 0.04 | J29: 0.04 | K29: 0.05 | L29: 0.05 | M29: 0.05 | N29: 0.05 | O29: 0.05 | P29: 0.05 | Q29: 0.05 | R29: 0.05 | S29: 0.04 | T29: 0.04 | U29: 0.04 | V29: 0.04 | W29: 0.03 | X29: 0.03 | Y29: 0.02 | Z29: 0.02 | AA29: 0.01 | AB29: 0.01 | AC29: 0.01 | AD29: 0.01 | AE29: 0.01 | AF29: 0.01 | AG29: 0 | AH29: 0 | AI29: 0 | AJ29: 0 | AK29: 0 | AL29: 0 | AM29: 0 | AN29: 0 | AO29: 0 | AP29: 0 | AQ29: 0 | AR29: 0 | AS29: 0 | AT29: 0 | AU29: 0 | AV29: 0 | AW29: 0 | AX29: 0 | AY29: 0 | AZ29: 0 | BA29: 0 | BB29: 0 | BC29: 0 | BD29: 0 | BE29: 0 | BF29: 0 | BG29: 0 | BH29: 0 | BI29: 0 | BJ29: 0 | BK29: =SUM(C29:BJ29) -> 1
A30: Ph 1h | B30: commercial | C30: 0.02 | D30: 0.03 | E30: 0.03 | F30: 0.04 | G30: 0.04 | H30: 0.04 | I30: 0.04 | J30: 0.04 | K30: 0.05 | L30: 0.05 | M30: 0.05 | N30: 0.05 | O30: 0.05 | P30: 0.05 | Q30: 0.05 | R30: 0.05 | S30: 0.04 | T30: 0.04 | U30: 0.04 | V30: 0.04 | W30: 0.03 | X30: 0.03 | Y30: 0.02 | Z30: 0.02 | AA30: 0.01 | AB30: 0.01 | AC30: 0.01 | AD30: 0.01 | AE30: 0.01 | AF30: 0.01 | AG30: 0 | AH30: 0 | AI30: 0 | AJ30: 0 | AK30: 0 | AL30: 0 | AM30: 0 | AN30: 0 | AO30: 0 | AP30: 0 | AQ30: 0 | AR30: 0 | AS30: 0 | AT30: 0 | AU30: 0 | AV30: 0 | AW30: 0 | AX30: 0 | AY30: 0 | AZ30: 0 | BA30: 0 | BB30: 0 | BC30: 0 | BD30: 0 | BE30: 0 | BF30: 0 | BG30: 0 | BH30: 0 | BI30: 0 | BJ30: 0 | BK30: =SUM(C30:BJ30) -> 1
A31: Ph 2a | B31: residential | C31: 0.01 | D31: 0.01 | E31: 0.01 | F31: 0.02 | G31: 0.02 | H31: 0.02 | I31: 0.02 | J31: 0.02 | K31: 0.02 | L31: 0.03 | M31: 0.03 | N31: 0.03 | O31: 0.03 | P31: 0.03 | Q31: 0.03 | R31: 0.04 | S31: 0.04 | T31: 0.04 | U31: 0.04 | V31: 0.04 | W31: 0.04 | X31: 0.04 | Y31: 0.03 | Z31: 0.03 | AA31: 0.03 | AB31: 0.03 | AC31: 0.03 | AD31: 0.02 | AE31: 0.02 | AF31: 0.02 | AG31: 0.02 | AH31: 0.02 | AI31: 0.02 | AJ31: 0.02 | AK31: 0.02 | AL31: 0.02 | AM31: 0.01 | AN31: 0.01 | AO31: 0.01 | AP31: 0.01 | AQ31: 0.01 | AR31: 0.01 | AS31: 0 | AT31: 0 | AU31: 0 | AV31: 0 | AW31: 0 | AX31: 0 | AY31: 0 | AZ31: 0 | BA31: 0 | BB31: 0 | BC31: 0 | BD31: 0 | BE31: 0 | BF31: 0 | BG31: 0 | BH31: 0 | BI31: 0 | BJ31: 0 | BK31: =SUM(C31:BJ31) -> 1
A32: Ph 2b | B32: residential | C32: 0.01 | D32: 0.01 | E32: 0.01 | F32: 0.02 | G32: 0.02 | H32: 0.02 | I32: 0.02 | J32: 0.02 | K32: 0.02 | L32: 0.03 | M32: 0.03 | N32: 0.03 | O32: 0.03 | P32: 0.03 | Q32: 0.03 | R32: 0.04 | S32: 0.04 | T32: 0.04 | U32: 0.04 | V32: 0.04 | W32: 0.04 | X32: 0.04 | Y32: 0.03 | Z32: 0.03 | AA32: 0.03 | AB32: 0.03 | AC32: 0.03 | AD32: 0.02 | AE32: 0.02 | AF32: 0.02 | AG32: 0.02 | AH32: 0.02 | AI32: 0.02 | AJ32: 0.02 | AK32: 0.02 | AL32: 0.02 | AM32: 0.01 | AN32: 0.01 | AO32: 0.01 | AP32: 0.01 | AQ32: 0.01 | AR32: 0.01 | AS32: 0 | AT32: 0 | AU32: 0 | AV32: 0 | AW32: 0 | AX32: 0 | AY32: 0 | AZ32: 0 | BA32: 0 | BB32: 0 | BC32: 0 | BD32: 0 | BE32: 0 | BF32: 0 | BG32: 0 | BH32: 0 | BI32: 0 | BJ32: 0 | BK32: =SUM(C32:BJ32) -> 1
A33: Ph 2c | B33: residential | C33: 0.01 | D33: 0.01 | E33: 0.01 | F33: 0.02 | G33: 0.02 | H33: 0.02 | I33: 0.02 | J33: 0.02 | K33: 0.02 | L33: 0.03 | M33: 0.03 | N33: 0.03 | O33: 0.03 | P33: 0.03 | Q33: 0.03 | R33: 0.04 | S33: 0.04 | T33: 0.04 | U33: 0.04 | V33: 0.04 | W33: 0.04 | X33: 0.04 | Y33: 0.03 | Z33: 0.03 | AA33: 0.03 | AB33: 0.03 | AC33: 0.03 | AD33: 0.02 | AE33: 0.02 | AF33: 0.02 | AG33: 0.02 | AH33: 0.02 | AI33: 0.02 | AJ33: 0.02 | AK33: 0.02 | AL33: 0.02 | AM33: 0.01 | AN33: 0.01 | AO33: 0.01 | AP33: 0.01 | AQ33: 0.01 | AR33: 0.01 | AS33: 0 | AT33: 0 | AU33: 0 | AV33: 0 | AW33: 0 | AX33: 0 | AY33: 0 | AZ33: 0 | BA33: 0 | BB33: 0 | BC33: 0 | BD33: 0 | BE33: 0 | BF33: 0 | BG33: 0 | BH33: 0 | BI33: 0 | BJ33: 0 | BK33: =SUM(C33:BJ33) -> 1
A34: Ph 2d | B34: residential | C34: 0.01 | D34: 0.01 | E34: 0.01 | F34: 0.02 | G34: 0.02 | H34: 0.02 | I34: 0.02 | J34: 0.02 | K34: 0.02 | L34: 0.03 | M34: 0.03 | N34: 0.03 | O34: 0.03 | P34: 0.03 | Q34: 0.03 | R34: 0.04 | S34: 0.04 | T34: 0.04 | U34: 0.04 | V34: 0.04 | W34: 0.04 | X34: 0.04 | Y34: 0.03 | Z34: 0.03 | AA34: 0.03 | AB34: 0.03 | AC34: 0.03 | AD34: 0.02 | AE34: 0.02 | AF34: 0.02 | AG34: 0.02 | AH34: 0.02 | AI34: 0.02 | AJ34: 0.02 | AK34: 0.02 | AL34: 0.02 | AM34: 0.01 | AN34: 0.01 | AO34: 0.01 | AP34: 0.01 | AQ34: 0.01 | AR34: 0.01 | AS34: 0 | AT34: 0 | AU34: 0 | AV34: 0 | AW34: 0 | AX34: 0 | AY34: 0 | AZ34: 0 | BA34: 0 | BB34: 0 | BC34: 0 | BD34: 0 | BE34: 0 | BF34: 0 | BG34: 0 | BH34: 0 | BI34: 0 | BJ34: 0 | BK34: =SUM(C34:BJ34) -> 1
... A40: Ph 2j | B40: commercial | C40: 0.02 | D40: 0.03 | E40: 0.03 | F40: 0.04 | G40: 0.04 | H40: 0.04 | I40: 0.04 | J40: 0.04 | K40: 0.05 | L40: 0.05 | M40: 0.05 | N40: 0.05 | O40: 0.05 | P40: 0.05 | Q40: 0.05 | R40: 0.05 | S40: 0.04 | T40: 0.04 | U40: 0.04 | V40: 0.04 | W40: 0.03 | X40: 0.03 | Y40: 0.02 | Z40: 0.02 | AA40: 0.01 | AB40: 0.01 | AC40: 0.01 | AD40: 0.01 | AE40: 0.01 | AF40: 0.01 | AG40: 0 | AH40: 0 | AI40: 0 | AJ40: 0 | AK40: 0 | AL40: 0 | AM40: 0 | AN40: 0 | AO40: 0 | AP40: 0 | AQ40: 0 | AR40: 0 | AS40: 0 | AT40: 0 | AU40: 0 | AV40: 0 | AW40: 0 | AX40: 0 | AY40: 0 | AZ40: 0 | BA40: 0 | BB40: 0 | BC40: 0 | BD40: 0 | BE40: 0 | BF40: 0 | BG40: 0 | BH40: 0 | BI40: 0 | BJ40: 0 | BK40: =SUM(C40:BJ40) -> 1
A42: C. SALES RECEIPTS (RM'000) — NDV × Monthly Absorption %
A43: Phase | B43: NDV (RM'000) | C43: Jan | D43: Feb | E43: Mar | F43: Apr | G43: May | H43: Jun | I43: Jul | J43: Aug | K43: Sep | L43: Oct | M43: Nov | N43: Dec | O43: Jan | P43: Feb | Q43: Mar | R43: Apr | S43: May | T43: Jun | U43: Jul | V43: Aug | W43: Sep | X43: Oct | Y43: Nov | Z43: Dec | AA43: Jan | AB43: Feb | AC43: Mar | AD43: Apr | AE43: May | AF43: Jun | AG43: Jul | AH43: Aug | AI43: Sep | AJ43: Oct | AK43: Nov | AL43: Dec | AM43: Jan | AN43: Feb | AO43: Mar | AP43: Apr | AQ43: May | AR43: Jun | AS43: Jul | AT43: Aug | AU43: Sep | AV43: Oct | AW43: Nov | AX43: Dec | AY43: Jan | AZ43: Feb | BA43: Mar | BB43: Apr | BC43: May | BD43: Jun | BE43: Jul | BF43: Aug | BG43: Sep | BH43: Oct | BI43: Nov | BJ43: Dec | BK43: Total
A44: Ph 1a | B44: ='Feasibility Study'!I73/1000 | C44: =IF($B$44=0,0,$B$44*C23) | D44: =IF($B$44=0,0,$B$44*D23) | E44: =IF($B$44=0,0,$B$44*E23) | F44: =IF($B$44=0,0,$B$44*F23) | G44: =IF($B$44=0,0,$B$44*G23) | H44: =IF($B$44=0,0,$B$44*H23) | I44: =IF($B$44=0,0,$B$44*I23) | J44: =IF($B$44=0,0,$B$44*J23) | ... BJ44: =IF($B$44=0,0,$B$44*BJ23) | BK44: =SUM(C44:BJ44)
A45: Ph 1b | B45: ='Feasibility Study'!K73/1000 | C45: =IF($B$45=0,0,$B$45*C24) | D45: =IF($B$45=0,0,$B$45*D24) | E45: =IF($B$45=0,0,$B$45*E24) | F45: =IF($B$45=0,0,$B$45*F24) | G45: =IF($B$45=0,0,$B$45*G24) | H45: =IF($B$45=0,0,$B$45*H24) | I45: =IF($B$45=0,0,$B$45*I24) | J45: =IF($B$45=0,0,$B$45*J24) | ... BJ45: =IF($B$45=0,0,$B$45*BJ24) | BK45: =SUM(C45:BJ45)
A46: Ph 1c | B46: ='Feasibility Study'!M73/1000 | C46: =IF($B$46=0,0,$B$46*C25) | D46: =IF($B$46=0,0,$B$46*D25) | E46: =IF($B$46=0,0,$B$46*E25) | F46: =IF($B$46=0,0,$B$46*F25) | G46: =IF($B$46=0,0,$B$46*G25) | H46: =IF($B$46=0,0,$B$46*H25) | I46: =IF($B$46=0,0,$B$46*I25) | J46: =IF($B$46=0,0,$B$46*J25) | ... BJ46: =IF($B$46=0,0,$B$46*BJ25) | BK46: =SUM(C46:BJ46)
A47: Ph 1d | B47: ='Feasibility Study'!O73/1000 | C47: =IF($B$47=0,0,$B$47*C26) | D47: =IF($B$47=0,0,$B$47*D26) | E47: =IF($B$47=0,0,$B$47*E26) | F47: =IF($B$47=0,0,$B$47*F26) | G47: =IF($B$47=0,0,$B$47*G26) | H47: =IF($B$47=0,0,$B$47*H26) | I47: =IF($B$47=0,0,$B$47*I26) | J47: =IF($B$47=0,0,$B$47*J26) | ... BJ47: =IF($B$47=0,0,$B$47*BJ26) | BK47: =SUM(C47:BJ47)
A48: Ph 1e | B48: ='Feasibility Study'!Q73/1000 | C48: =IF($B$48=0,0,$B$48*C27) | D48: =IF($B$48=0,0,$B$48*D27) | E48: =IF($B$48=0,0,$B$48*E27) | F48: =IF($B$48=0,0,$B$48*F27) | G48: =IF($B$48=0,0,$B$48*G27) | H48: =IF($B$48=0,0,$B$48*H27) | I48: =IF($B$48=0,0,$B$48*I27) | J48: =IF($B$48=0,0,$B$48*J27) | ... BJ48: =IF($B$48=0,0,$B$48*BJ27) | BK48: =SUM(C48:BJ48)
...

Sheet IRR & Sensitivity
A1: BRDB LAND — IRR, NPV & SENSITIVITY ANALYSIS
A2: XIRR on 60 monthly cashflows | 5 sensitivity tables | Blue = inputs | Yellow = base case | Green ≥ hurdle | Red < hurdle
A4: A. ASSUMPTIONS & LIVE METRICS | E4: B. SENSITIVITY 1 — PROJECT IRR (%) vs ASP psf × Absorption Rate
A5: Base ASP (RM psf) | B5: 680 | E5: IRR scales proportionally from live XIRR with revenue (ASP × absorption). Accurate within ±15% of base. For exact values, edit inputs in Cashflow sheet.
A6: Base absorption rate | B6: 0.8 | E6: ASP psf ↓ Absorption → | F6: 50% | G6: 60% | H6: 70% | I6: ★ 80% | J6: 90% | K6: 100% | L6: 110%
A7: Base build cost (RM psf) | B7: 280 | E7: RM 476 (−30%) | F7: =IFERROR(Returns!B81*0.7*0.625,0) | G7: =IFERROR(Returns!B81*0.7*0.75,0) | H7: =IFERROR(Returns!B81*0.7*0.875,0) | I7: =IFERROR(Returns!B81*0.7*1,0) | J7: =IFERROR(Returns!B81*0.7*1.125,0) | K7: =IFERROR(Returns!B81*0.7*1.25,0) | L7: =IFERROR(Returns!B81*0.7*1.375,0)
A8: Target hurdle IRR | B8: =Cashflow!B18 -> 0.16 | E8: RM 544 (−20%) | F8: =IFERROR(Returns!B81*0.8*0.625,0) | G8: =IFERROR(Returns!B81*0.8*0.75,0) | H8: =IFERROR(Returns!B81*0.8*0.875,0) | I8: =IFERROR(Returns!B81*0.8*1,0) | J8: =IFERROR(Returns!B81*0.8*1.125,0) | K8: =IFERROR(Returns!B81*0.8*1.25,0) | L8: =IFERROR(Returns!B81*0.8*1.375,0)
A9: Annual interest rate | B9: =Cashflow!B17 -> 0.0455 | E9: RM 612 (−10%) | F9: =IFERROR(Returns!B81*0.9*0.625,0) | G9: =IFERROR(Returns!B81*0.9*0.75,0) | H9: =IFERROR(Returns!B81*0.9*0.875,0) | I9: =IFERROR(Returns!B81*0.9*1,0) | J9: =IFERROR(Returns!B81*0.9*1.125,0) | K9: =IFERROR(Returns!B81*0.9*1.25,0) | L9: =IFERROR(Returns!B81*0.9*1.375,0)
A10: Development period (yrs) | B10: =Cashflow!B9 -> 5 | E10: RM 680 ★ Base | F10: =IFERROR(Returns!B81*1*0.625,0) | G10: =IFERROR(Returns!B81*1*0.75,0) | H10: =IFERROR(Returns!B81*1*0.875,0) | I10: =IFERROR(Returns!B81*1*1,0) | J10: =IFERROR(Returns!B81*1*1.125,0) | K10: =IFERROR(Returns!B81*1*1.25,0) | L10: =IFERROR(Returns!B81*1*1.375,0)
E11: RM 748 (+10%) | F11: =IFERROR(Returns!B81*1.1*0.625,0) | G11: =IFERROR(Returns!B81*1.1*0.75,0) | H11: =IFERROR(Returns!B81*1.1*0.875,0) | I11: =IFERROR(Returns!B81*1.1*1,0) | J11: =IFERROR(Returns!B81*1.1*1.125,0) | K11: =IFERROR(Returns!B81*1.1*1.25,0) | L11: =IFERROR(Returns!B81*1.1*1.375,0)
A12: LIVE MODEL OUTPUTS | E12: RM 816 (+20%) | F12: =IFERROR(Returns!B81*1.2*0.625,0) | G12: =IFERROR(Returns!B81*1.2*0.75,0) | H12: =IFERROR(Returns!B81*1.2*0.875,0) | I12: =IFERROR(Returns!B81*1.2*1,0) | J12: =IFERROR(Returns!B81*1.2*1.125,0) | K12: =IFERROR(Returns!B81*1.2*1.25,0) | L12: =IFERROR(Returns!B81*1.2*1.375,0)
A13: Total GDV (RM'000) | B13: =Returns!B5 | E13: RM 884 (+30%) | F13: =IFERROR(Returns!B81*1.3*0.625,0) | G13: =IFERROR(Returns!B81*1.3*0.75,0) | H13: =IFERROR(Returns!B81*1.3*0.875,0) | I13: =IFERROR(Returns!B81*1.3*1,0) | J13: =IFERROR(Returns!B81*1.3*1.125,0) | K13: =IFERROR(Returns!B81*1.3*1.25,0) | L13: =IFERROR(Returns!B81*1.3*1.375,0)
A14: Total NDV (RM'000) | B14: =Returns!B6 -> 0
A15: Total GDC (RM'000) | B15: =Returns!B7 -> 0
A16: NDP (RM'000) | B16: =Returns!B8 -> 0 | E16: C. SENSITIVITY 2 — NDP MARGIN (%) vs ASP psf × Absorption Rate
A17: Dev margin % on NDV | B17: =Returns!B9 -> 0 | E17: NDP margin = (NDV × ASP_factor × Abs_factor − GDC) / (NDV × ASP_factor × Abs_factor). GDC treated as fixed.
A18: Land cost (RM'000) | B18: =Cashflow!B15 -> 0 | E18: ASP psf ↓ Absorption → | F18: 50% | G18: 60% | H18: 70% | I18: ★ 80% | J18: 90% | K18: 100% | L18: 110%
A19: Construction cost (RM'000) | B19: =Cashflow!B16 -> #DIV/0! | E19: RM 476 (−30%) | F19: =IFERROR((Returns!B6*0.7*0.625-Returns!B7)/(Returns!B6*0.7*0.625),0) -> 0 | G19: =IFERROR((Returns!B6*0.7*0.75-Returns!B7)/(Returns!B6*0.7*0.75),0) -> 0 | H19: =IFERROR((Returns!B6*0.7*0.875-Returns!B7)/(Returns!B6*0.7*0.875),0) -> 0 | I19: =IFERROR((Returns!B6*0.7*1-Returns!B7)/(Returns!B6*0.7*1),0) -> 0 | J19: =IFERROR((Returns!B6*0.7*1.125-Returns!B7)/(Returns!B6*0.7*1.125),0) -> 0 | K19: =IFERROR((Returns!B6*0.7*1.25-Returns!B7)/(Returns!B6*0.7*1.25),0) -> 0 | L19: =IFERROR((Returns!B6*0.7*1.375-Returns!B7)/(Returns!B6*0.7*1.375),0) -> 0
A20: Peak equity (RM'000) | B20: =Returns!B12 | E20: RM 544 (−20%) | F20: =IFERROR((Returns!B6*0.8*0.625-Returns!B7)/(Returns!B6*0.8*0.625),0) -> 0 | G20: =IFERROR((Returns!B6*0.8*0.75-Returns!B7)/(Returns!B6*0.8*0.75),0) -> 0 | H20: =IFERROR((Returns!B6*0.8*0.875-Returns!B7)/(Returns!B6*0.8*0.875),0) -> 0 | I20: =IFERROR((Returns!B6*0.8*1-Returns!B7)/(Returns!B6*0.8*1),0) -> 0 | J20: =IFERROR((Returns!B6*0.8*1.125-Returns!B7)/(Returns!B6*0.8*1.125),0) -> 0 | K20: =IFERROR((Returns!B6*0.8*1.25-Returns!B7)/(Returns!B6*0.8*1.25),0) -> 0 | L20: =IFERROR((Returns!B6*0.8*1.375-Returns!B7)/(Returns!B6*0.8*1.375),0) -> 0
A21: MOIC | B21: =IFERROR(Returns!B8/ABS(Returns!B12),0) | E21: RM 612 (−10%) | F21: =IFERROR((Returns!B6*0.9*0.625-Returns!B7)/(Returns!B6*0.9*0.625),0) -> 0 | G21: =IFERROR((Returns!B6*0.9*0.75-Returns!B7)/(Returns!B6*0.9*0.75),0) -> 0 | H21: =IFERROR((Returns!B6*0.9*0.875-Returns!B7)/(Returns!B6*0.9*0.875),0) -> 0 | I21: =IFERROR((Returns!B6*0.9*1-Returns!B7)/(Returns!B6*0.9*1),0) -> 0 | J21: =IFERROR((Returns!B6*0.9*1.125-Returns!B7)/(Returns!B6*0.9*1.125),0) -> 0 | K21: =IFERROR((Returns!B6*0.9*1.25-Returns!B7)/(Returns!B6*0.9*1.25),0) -> 0 | L21: =IFERROR((Returns!B6*0.9*1.375-Returns!B7)/(Returns!B6*0.9*1.375),0) -> 0
E22: RM 680 ★ Base | F22: =IFERROR((Returns!B6*1*0.625-Returns!B7)/(Returns!B6*1*0.625),0) -> 0 | G22: =IFERROR((Returns!B6*1*0.75-Returns!B7)/(Returns!B6*1*0.75),0) -> 0 | H22: =IFERROR((Returns!B6*1*0.875-Returns!B7)/(Returns!B6*1*0.875),0) -> 0 | I22: =IFERROR((Returns!B6*1*1-Returns!B7)/(Returns!B6*1*1),0) -> 0 | J22: =IFERROR((Returns!B6*1*1.125-Returns!B7)/(Returns!B6*1*1.125),0) -> 0 | K22: =IFERROR((Returns!B6*1*1.25-Returns!B7)/(Returns!B6*1*1.25),0) -> 0 | L22: =IFERROR((Returns!B6*1*1.375-Returns!B7)/(Returns!B6*1*1.375),0) -> 0
A23: XIRR RETURN METRICS | E23: RM 748 (+10%) | F23: =IFERROR((Returns!B6*1.1*0.625-Returns!B7)/(Returns!B6*1.1*0.625),0) -> 0 | G23: =IFERROR((Returns!B6*1.1*0.75-Returns!B7)/(Returns!B6*1.1*0.75),0) -> 0 | H23: =IFERROR((Returns!B6*1.1*0.875-Returns!B7)/(Returns!B6*1.1*0.875),0) -> 0 | I23: =IFERROR((Returns!B6*1.1*1-Returns!B7)/(Returns!B6*1.1*1),0) -> 0 | J23: =IFERROR((Returns!B6*1.1*1.125-Returns!B7)/(Returns!B6*1.1*1.125),0) -> 0 | K23: =IFERROR((Returns!B6*1.1*1.25-Returns!B7)/(Returns!B6*1.1*1.25),0) -> 0 | L23: =IFERROR((Returns!B6*1.1*1.375-Returns!B7)/(Returns!B6*1.1*1.375),0) -> 0
A24: Project IRR (XIRR monthly) | B24: =Returns!B81 | E24: RM 816 (+20%) | F24: =IFERROR((Returns!B6*1.2*0.625-Returns!B7)/(Returns!B6*1.2*0.625),0) -> 0 | G24: =IFERROR((Returns!B6*1.2*0.75-Returns!B7)/(Returns!B6*1.2*0.75),0) -> 0 | H24: =IFERROR((Returns!B6*1.2*0.875-Returns!B7)/(Returns!B6*1.2*0.875),0) -> 0 | I24: =IFERROR((Returns!B6*1.2*1-Returns!B7)/(Returns!B6*1.2*1),0) -> 0 | J24: =IFERROR((Returns!B6*1.2*1.125-Returns!B7)/(Returns!B6*1.2*1.125),0) -> 0 | K24: =IFERROR((Returns!B6*1.2*1.25-Returns!B7)/(Returns!B6*1.2*1.25),0) -> 0 | L24: =IFERROR((Returns!B6*1.2*1.375-Returns!B7)/(Returns!B6*1.2*1.375),0) -> 0
A25: NPV @ 12% hurdle (RM'000) | B25: =Returns!B83 | E25: RM 884 (+30%) | F25: =IFERROR((Returns!B6*1.3*0.625-Returns!B7)/(Returns!B6*1.3*0.625),0) -> 0 | G25: =IFERROR((Returns!B6*1.3*0.75-Returns!B7)/(Returns!B6*1.3*0.75),0) -> 0 | H25: =IFERROR((Returns!B6*1.3*0.875-Returns!B7)/(Returns!B6*1.3*0.875),0) -> 0 | I25: =IFERROR((Returns!B6*1.3*1-Returns!B7)/(Returns!B6*1.3*1),0) -> 0 | J25: =IFERROR((Returns!B6*1.3*1.125-Returns!B7)/(Returns!B6*1.3*1.125),0) -> 0 | K25: =IFERROR((Returns!B6*1.3*1.25-Returns!B7)/(Returns!B6*1.3*1.25),0) -> 0 | L25: =IFERROR((Returns!B6*1.3*1.375-Returns!B7)/(Returns!B6*1.3*1.375),0) -> 0
A26: NPV @ 15% hurdle (RM'000) | B26: =Returns!B84
A27: NPV @ 18% hurdle (RM'000) | B27: =Returns!B85
A28: Payback period (months) | B28: =Returns!B90 | E28: D. SENSITIVITY 3 — NPV (RM'000) vs Discount Rate × Absorption Rate
E29: Direct NPV() on 60 monthly cashflows from Returns sheet. Scaled by absorption factor. Negative NPV = project destroys value at that rate.
A30: COLOUR KEY | E30: Disc. rate ↓ Absorption → | F30: 50% | G30: 60% | H30: 70% | I30: ★ 80% | J30: 90% | K30: 100% | L30: 110%
A31: Base case (RM 680 psf / 80% absorption) | E31: 8% | F31: =IFERROR(NPV(0.08/12,Returns!C19:C78)*0.625,0) | G31: =IFERROR(NPV(0.08/12,Returns!C19:C78)*0.75,0) | H31: =IFERROR(NPV(0.08/12,Returns!C19:C78)*0.875,0) | I31: =IFERROR(NPV(0.08/12,Returns!C19:C78)*1,0) | J31: =IFERROR(NPV(0.08/12,Returns!C19:C78)*1.125,0) | K31: =IFERROR(NPV(0.08/12,Returns!C19:C78)*1.25,0) | L31: =IFERROR(NPV(0.08/12,Returns!C19:C78)*1.375,0)
A32: At/above hurdle IRR or NDP margin ≥ 25% | E32: 10% | F32: =IFERROR(NPV(0.1/12,Returns!C19:C78)*0.625,0) | G32: =IFERROR(NPV(0.1/12,Returns!C19:C78)*0.75,0) | H32: =IFERROR(NPV(0.1/12,Returns!C19:C78)*0.875,0) | I32: =IFERROR(NPV(0.1/12,Returns!C19:C78)*1,0) | J32: =IFERROR(NPV(0.1/12,Returns!C19:C78)*1.125,0) | K32: =IFERROR(NPV(0.1/12,Returns!C19:C78)*1.25,0) | L32: =IFERROR(NPV(0.1/12,Returns!C19:C78)*1.375,0)
A33: Within 3% below hurdle / margin 15–25% | E33: 12% | F33: =IFERROR(NPV(0.12/12,Returns!C19:C78)*0.625,0) | G33: =IFERROR(NPV(0.12/12,Returns!C19:C78)*0.75,0) | H33: =IFERROR(NPV(0.12/12,Returns!C19:C78)*0.875,0) | I33: =IFERROR(NPV(0.12/12,Returns!C19:C78)*1,0) | J33: =IFERROR(NPV(0.12/12,Returns!C19:C78)*1.125,0) | K33: =IFERROR(NPV(0.12/12,Returns!C19:C78)*1.25,0) | L33: =IFERROR(NPV(0.12/12,Returns!C19:C78)*1.375,0)
A34: More than 3% below hurdle / margin < 15% | E34: 15% | F34: =IFERROR(NPV(0.15/12,Returns!C19:C78)*0.625,0) | G34: =IFERROR(NPV(0.15/12,Returns!C19:C78)*0.75,0) | H34: =IFERROR(NPV(0.15/12,Returns!C19:C78)*0.875,0) | I34: =IFERROR(NPV(0.15/12,Returns!C19:C78)*1,0) | J34: =IFERROR(NPV(0.15/12,Returns!C19:C78)*1.125,0) | K34: =IFERROR(NPV(0.15/12,Returns!C19:C78)*1.25,0) | L34: =IFERROR(NPV(0.15/12,Returns!C19:C78)*1.375,0)
E35: ★ 16% | F35: =IFERROR(NPV(0.16/12,Returns!C19:C78)*0.625,0) | G35: =IFERROR(NPV(0.16/12,Returns!C19:C78)*0.75,0) | H35: =IFERROR(NPV(0.16/12,Returns!C19:C78)*0.875,0) | I35: =IFERROR(NPV(0.16/12,Returns!C19:C78)*1,0) | J35: =IFERROR(NPV(0.16/12,Returns!C19:C78)*1.125,0) | K35: =IFERROR(NPV(0.16/12,Returns!C19:C78)*1.25,0) | L35: =IFERROR(NPV(0.16/12,Returns!C19:C78)*1.375,0)
E36: 18% | F36: =IFERROR(NPV(0.18/12,Returns!C19:C78)*0.625,0) | G36: =IFERROR(NPV(0.18/12,Returns!C19:C78)*0.75,0) | H36: =IFERROR(NPV(0.18/12,Returns!C19:C78)*0.875,0) | I36: =IFERROR(NPV(0.18/12,Returns!C19:C78)*1,0) | J36: =IFERROR(NPV(0.18/12,Returns!C19:C78)*1.125,0) | K36: =IFERROR(NPV(0.18/12,Returns!C19:C78)*1.25,0) | L36: =IFERROR(NPV(0.18/12,Returns!C19:C78)*1.375,0)
E37: 20% | F37: =IFERROR(NPV(0.2/12,Returns!C19:C78)*0.625,0) | G37: =IFERROR(NPV(0.2/12,Returns!C19:C78)*0.75,0) | H37: =IFERROR(NPV(0.2/12,Returns!C19:C78)*0.875,0) | I37: =IFERROR(NPV(0.2/12,Returns!C19:C78)*1,0) | J37: =IFERROR(NPV(0.2/12,Returns!C19:C78)*1.125,0) | K37: =IFERROR(NPV(0.2/12,Returns!C19:C78)*1.25,0) | L37: =IFERROR(NPV(0.2/12,Returns!C19:C78)*1.375,0)
E40: E. SENSITIVITY 4 — NDP MARGIN (%) vs Build Cost × ASP psf
E41: Construction cost varies ±30% from RM 280 psf base. GDC adjusted pro-rata. Revenue = NDV × ASP_factor at base absorption.
E42: Build cost ↓ ASP psf → | F42: RM 476 (−30%) | G42: RM 544 (−20%) | H42: RM 612 (−10%) | I42: RM 680 ★ Base | J42: RM 748 (+10%) | K42: RM 816 (+20%)
E43: RM 196 (−30%) | F43: =IFERROR((Returns!B6*0.7-(Returns!B7+Cashflow!B16*-0.3))/(Returns!B6*0.7),0) -> 0 | G43: =IFERROR((Returns!B6*0.8-(Returns!B7+Cashflow!B16*-0.3))/(Returns!B6*0.8),0) -> 0 | H43: =IFERROR((Returns!B6*0.9-(Returns!B7+Cashflow!B16*-0.3))/(Returns!B6*0.9),0) -> 0 | I43: =IFERROR((Returns!B6*1-(Returns!B7+Cashflow!B16*-0.3))/(Returns!B6*1),0) -> 0 | J43: =IFERROR((Returns!B6*1.1-(Returns!B7+Cashflow!B16*-0.3))/(Returns!B6*1.1),0) -> 0 | K43: =IFERROR((Returns!B6*1.2-(Returns!B7+Cashflow!B16*-0.3))/(Returns!B6*1.2),0) -> 0
...

Sheet Returns
A1: BRDB LAND — RETURNS & SENSITIVITY ANALYSIS
A2: All values RM'000 | XIRR on 60 monthly cashflows | Blue = inputs | Green = linked from other sheets
A4: A. PROJECT SUMMARY
A5: Total GDV (RM'000) | B5: ='Feasibility Study'!AY65/1000
A6: Total NDV (RM'000) | B6: ='Feasibility Study'!AY73/1000 -> 0
A7: Gross dev cost — GDC (RM'000) | B7: ='Feasibility Study'!AY157/1000 -> 0
A8: Net dev profit — NDP (RM'000) | B8: ='Feasibility Study'!AY170/1000 -> 0
A9: Dev margin % on NDV | B9: =IF(B6=0,0,B8/B6) -> 0
A10: Land cost (RM'000) | B10: ='Feasibility Study'!AY82/1000 -> 0
A11: Construction cost (RM'000) | B11: ='Feasibility Study'!AY87/1000 -> #DIV/0!
A12: Peak equity exposure (RM'000) | B12: =Cashflow!BK98
A13: Development period (years) | B13: =Cashflow!B8 -> BRDB Land Development
A16: B. EQUITY CASHFLOW SCHEDULE — Input for XIRR
A17: Equity invested = outflows up to peak; equity repaid = inflows after peak. Dates set to quarterly from project start.
A18: Quarter | B18: Date | C18: Net CF (RM'000) | D18: Cumulative (RM'000)
A19: Y1 M01 | B19: 46023 | C19: =Cashflow!C97 | D19: =Cashflow!C98
A20: Y1 M02 | B20: 46054 | C20: =Cashflow!D97 | D20: =Cashflow!D98
A21: Y1 M03 | B21: 46082 | C21: =Cashflow!E97 | D21: =Cashflow!E98
A22: Y1 M04 | B22: 46113 | C22: =Cashflow!F97 | D22: =Cashflow!F98
A23: Y1 M05 | B23: 46143 | C23: =Cashflow!G97 | D23: =Cashflow!G98
A24: Y1 M06 | B24: 46174 | C24: =Cashflow!H97 | D24: =Cashflow!H98
A25: Y1 M07 | B25: 46204 | C25: =Cashflow!I97 | D25: =Cashflow!I98
A26: Y1 M08 | B26: 46235 | C26: =Cashflow!J97 | D26: =Cashflow!J98
A27: Y1 M09 | B27: 46266 | C27: =Cashflow!K97 | D27: =Cashflow!K98
A28: Y1 M10 | B28: 46296 | C28: =Cashflow!L97 | D28: =Cashflow!L98
A29: Y1 M11 | B29: 46327 | C29: =Cashflow!M97 | D29: =Cashflow!M98
A30: Y1 M12 | B30: 46357 | C30: =Cashflow!N97 | D30: =Cashflow!N98
A31: Y2 M01 | B31: 46388 | C31: =Cashflow!O97 | D31: =Cashflow!O98
A32: Y2 M02 | B32: 46419 | C32: =Cashflow!P97 | D32: =Cashflow!P98
A33: Y2 M03 | B33: 46447 | C33: =Cashflow!Q97 | D33: =Cashflow!Q98
A34: Y2 M04 | B34: 46478 | C34: =Cashflow!R97 | D34: =Cashflow!R98
A35: Y2 M05 | B35: 46508 | C35: =Cashflow!S97 | D35: =Cashflow!S98
A36: Y2 M06 | B36: 46539 | C36: =Cashflow!T97 | D36: =Cashflow!T98
A37: Y2 M07 | B37: 46569 | C37: =Cashflow!U97 | D37: =Cashflow!U98
A38: Y2 M08 | B38: 46600 | C38: =Cashflow!V97 | D38: =Cashflow!V98
A39: Y2 M09 | B39: 46631 | C39: =Cashflow!W97 | D39: =Cashflow!W98
A40: Y2 M10
A41: Y2 M11 | B41: 46692 | C41: =Cashflow!Y97 | D41: =Cashflow!Y98
A42: Y2 M12 | B42: 46722 | C42: =Cashflow!Z97 | D42: =Cashflow!Z98
A43: Y3 M01 | B43: 46753 | C43: =Cashflow!AA97 | D43: =Cashflow!AA98
...
