Workbook
Name x: #N/A

Sheet Feasibility Study
A1: BRDB Development Sdn Bhd
A2: Feasibility Study
A3: Lot 1423, Jalan Desa Sentosa KL | G3: Acre to Sqm | H3: 4046.87
G4: Acre to Sqft | H4: 43560 | I4: Jalan Desa Sentosa | K4: Phase 1b | M4: Phase 1c | O4: Phase 1d | Q4: Phase 1e | S4: Phase 1f | W4: Phase 1g | Y4: Phase 1h | AC4: Phase 2a | AE4: Phase 2B | AG4: Phase 2c | AI4: Phase 2d | AK4: Phase 2e | AM4: Phase 2f | AO4: Phase 2g1 | AQ4: Phase 2g2 | AS4: Phase 2g3 | AU4: Phase 2h
A6: LAUNCH DATE | I6: TBC | K6: TBC | M6: TBC | O6: TBC | Q6: TBC | S6: TBC | W6: TBC | Y6: TBC | AC6: TBC | AE6: TBC | AG6: TBC | AI6: TBC | AK6: TBC | AM6: TBC | AO6: TBC | AQ6: TBC | AS6: TBC | AU6: TBC | AW6: TBC | AY6: TOTAL
C8: Phases Land Area (acres) => | I8: 2.938 | K8: 0 | M8: 0 | O8: 0 | Q8: 0 | S8: 0 | W8: 0 | Y8: 0 | AC8: 0 | AE8: 0 | AG8: 0 | AI8: 0 | AK8: 0 | AM8: 0 | AO8: 0 | AQ8: 0 | AS8: 0 | AU8: 0 | AW8: 0 | AY8: =SUM(I8:AW8) -> 2.938
C9: Phases Land Area (square meter) => | I9: =I8*$H$3 -> 11889.704 | K9: =K8*$H$3 -> 0 | M9: =M8*$H$3 -> 0 | O9: =O8*$H$3 -> 0 | Q9: =Q8*$H$3 -> 0 | S9: =S8*$H$3 -> 0 | W9: =W8*$H$3 -> 0 | Y9: =Y8*$H$3 -> 0 | AC9: =AC8*$H$3 -> 0 | AE9: =AE8*$H$3 -> 0 | AG9: =AG8*$H$3 -> 0 | AI9: =AI8*$H$3 -> 0 | AK9: =AK8*$H$3 -> 0 | AM9: =AM8*$H$3 -> 0 | AO9: =AO8*$H$3 -> 0 | AQ9: =AQ8*$H$3 -> 0 | AS9: =AS8*$H$3 -> 0 | AU9: =AU8*$H$3 -> 0 | AW9: =AW8*$H$3 -> 0 | AY9: =SUM(I9:AW9) -> 11889.704
C10: Phases Land Area (square feet) => | I10: =I8*$H$4 -> 127979.28 | K10: =K8*$H$4 -> 0 | M10: =M8*$H$4 -> 0 | O10: =O8*$H$4 -> 0 | Q10: =Q8*$H$4 -> 0 | S10: =S8*$H$4 -> 0 | W10: =W8*$H$4 -> 0 | Y10: =Y8*$H$4 -> 0 | AC10: =AC8*$H$4 -> 0 | AE10: =AE8*$H$4 -> 0 | AG10: =AG8*$H$4 -> 0 | AI10: =AI8*$H$4 -> 0 | AK10: =AK8*$H$4 -> 0 | AM10: =AM8*$H$4 -> 0 | AO10: =AO8*$H$4 -> 0 | AQ10: =AQ8*$H$4 -> 0 | AS10: =AS8*$H$4 -> 0 | AU10: =AU8*$H$4 -> 0 | AW10: =AW8*$H$4 -> 0 | AY10: =SUM(I10:AW10) -> 127979.28
C11: No of units in the Phase => | I11: =E36 -> 84 | K11: =#REF! -> #REF! | M11: =#REF! -> #REF! | O11: =#REF! -> #REF! | Q11: 0 | S11: =#REF!+#REF! -> #REF! | W11: =#REF! -> #REF! | Y11: =#REF! -> #REF! | AC11: =#REF! -> #REF! | AE11: =#REF! -> #REF! | AG11: =#REF! -> #REF! | AI11: =#REF! -> #REF! | AK11: =#REF! -> #REF! | AM11: =#REF! -> #REF! | AO11: =#REF! -> #REF! | AQ11: =#REF! -> #REF! | AS11: 0 | AU11: =#REF! -> #REF! | AW11: =#REF! -> #REF! | AY11: =SUM(I11:AW11) -> #REF!
C12: Carpark Bays => | I12: 344 | K12: 0 | M12: 0 | O12: 0 | Q12: 0 | S12: 0
C13: Typical Apartment Floor => | I13: 44
C14: Construction Floor Area include Carpark (CFA) => | I14: 653039
C15: Gross Floor Area exclude Carpark (GFA) => | I15: 378439 | M15: 1
C16: Net Floor/Saleable area (NFA) => | I16: =G36 -> 294000 | M16: =M11*#REF! -> #REF! | O16: =O11*#REF! -> #REF! | Q16: =Q11*#REF! -> #REF! | S16: =(#REF!*#REF!)+(#REF!*#REF!) -> #REF! | W16: =W11*#REF! -> #REF! | Y16: =Y11*#REF! -> #REF! | AC16: =AC11*#REF! -> #REF! | AE16: =AE11*#REF! -> #REF! | AG16: =AG11*#REF! -> #REF! | AI16: =AI11*#REF! -> #REF! | AK16: =AK11*#REF! -> #REF! | AM16: =AM11*#REF! -> #REF! | AO16: =AO11*#REF! -> #REF! | AQ16: =AQ11*#REF! -> #REF! | AS16: =AS11*#REF! -> #REF! | AU16: =AU11*#REF! -> #REF! | AW16: =AW11*#REF! -> #REF! | AY16: =SUM(I16:AW16) -> #REF!
C17: Plot Ratio (commercial) / Density (per acres) => | I17: =I15/I10 -> 2.9570334 | K17: =K11/K8 -> #REF! | M17: =M11/M8 -> #REF! | O17: =O11/O8 -> #REF! | Q17: =Q16/Q10 -> #REF! | S17: =S16/S10 -> #REF! | W17: =W16/W10 -> #REF! | Y17: =Y16/Y10 -> #REF! | AC17: =AC11/AC8 -> #REF! | AE17: =AE11/AE8 -> #REF! | AG17: =AG11/AG8 -> #REF! | AI17: =AI11/AI8 -> #REF! | AK17: =AK11/AK8 -> #REF! | AM17: =AM11/AM8 -> #REF! | AO17: =AO11/AO8 -> #REF! | AQ17: =AQ11/AQ8 -> #REF! | AS17: =AS11/AS8 -> #DIV/0! | AU17: =AU11/AU8 -> #REF! | AW17: =AW16/AW10 -> #REF!
C19: Summary | H19: %
C20: Net Development Value (NDV) => | G20: =F36 -> 600 | H20: =I20/$I$20 -> 1 | I20: =I61 -> 176400000
C21: Land Cost => | G21: =F72 -> 100 | H21: =-I21/$I$20 -> 0.084952244 | I21: =-I69 -> -14985576
C22: Construction Cost => | G22: =I81 -> 352.47134 | H22: =-I22/$I$20 -> 0.58745224 | I22: =-I79 -> -1.0362657e+08
C23: Soft Cost => | G23: =-I23/I16 -> 48.442244 | H23: =-I23/$I$20 -> 0.080737073 | I23: =-I103-I106-I109-I122-I125-I129-I132 -> -14242020
C24: Finance Cost => | H24: =-I24/$I$20 -> 0.030626209 | I24: =-I144 -> -5402463.3
C25: Net Development Profit (NDP) => | I25: =SUM(I20:I24) -> 38143367
H26: Net Profit Margin | I26: =I25/I20 -> 0.21623224
A28: A | B28: GROSS DEVELOPMENT VALUE
S29: Mixed Comm | W29: Mixed Comm | Y29: Mixed Comm
A30: 1 | B30: Type of Development | I30: Condominium | K30: 3 Sty Superlink | M30: Affordable Home | O30: Affordable Home | Q30: Commercial | S30: S. Apartment | W30: S.Apartment | Y30: S.Apartment | AC30: 2 Sty Linkhouse | AE30: 2 Sty Linkhouse | AG30: 2 Sty Linkhouse | AI30: 2 Sty Semi-D | AK30: 2 Sty Semi-D | AM30: Zero Lot Bungalow | AO30: Condominium | AQ30: Condominium | AS30: Recreational | AU30: Terrace House | AW30: Commercial Shoplot
A31: =A30+1 -> 2 | B31: Total No of Units | C31: a) Residential | D31: =E36 -> 84 | Q31: Shop-lot | S31: Retail Shoplots | W31: Retail Shoplots | Y31: Retail Shoplots | AO31: High Rise | AQ31: High Rise | AS31: Park
A32: =A31+1 -> 3 | B32: Net Floor/Saleable Area (NFA) | C32: a) Residential | D32: =E36*D36 -> 294000
A33: =A32+1 -> 4 | B33: Net Selling Price psf | C33: a) Residential | D33: =F36 -> 600 | K33: =K61/K16 -> #REF! | M33: =M61/M16 -> #REF! | O33: =O61/O16 -> #REF! | Q33: =Q61/Q16 -> #REF! | S33: =S61/S16 -> #REF! | W33: =W61/W16 -> #REF! | Y33: =Y61/Y16 -> #REF! | AC33: =AC61/AC16 -> #REF! | AE33: =AE61/AE16 -> #REF! | AG33: =AG61/AG16 -> #REF! | AI33: =AI61/AI16 -> #REF! | AK33: =AK61/AK16 -> #REF! | AM33: =AM61/AM16 -> #REF! | AO33: =AO61/AO16 -> #REF! | AQ33: =AQ61/AQ16 -> #REF! | AS33: =AS61/AS16 -> #REF! | AU33: =AU61/AU16 -> #REF! | AW33: =AW61/AW16 -> #REF!
D34: Unit Avg size | E34: Units | F34: RM'psf (Nett to Dev) | G34: Total NFA | H34: Average Price/unit (Nett)
C35: Condominium | K35: =#REF!*#REF!/2 -> #REF! | AY35: =SUM(I35:AW35) -> #REF!
C36: Typical Apartment (2 units per floor) | D36: 3500 | E36: 84 | F36: 600 | G36: =E36*D36 -> 294000 | H36: =D36*F36 -> 2100000
A38: GROSS DEVELOPMENT VALUE (GDV) | I38: =SUM(I40:I61) -> 220229268 | K38: =SUM(K39:K61) -> #REF! | M38: =SUM(M39:M61) -> #REF! | O38: =SUM(O39:O61) -> #REF! | Q38: =SUM(Q39:Q61) -> #REF! | S38: =SUM(S39:S61) -> #REF! | W38: =SUM(W39:W61) -> #REF! | Y38: =SUM(Y39:Y61) -> #REF! | AC38: =SUM(AC39:AC61) -> #REF! | AE38: =SUM(AE39:AE61) -> #REF! | AG38: =SUM(AG39:AG61) -> #REF! | AI38: =SUM(AI39:AI61) -> #REF! | AK38: =SUM(AK39:AK61) -> #REF! | AM38: =SUM(AM39:AM61) -> #REF! | AO38: =SUM(AO39:AO61) -> #REF! | AQ38: =SUM(AQ39:AQ61) -> #REF! | AS38: =SUM(AS39:AS61) -> #REF! | AU38: =SUM(AU39:AU61) -> #REF! | AW38: =SUM(AW39:AW61) -> #REF! | AY38: =SUM(AY39:AY61) -> #REF!
A39: 1 | B39: MARKETING & SELLING EXPENSES | I39: =SUM(I40:I60) -> 43829268 | K39: =#REF!+#REF! -> #REF! | M39: =#REF! -> #REF! | O39: =#REF! -> #REF! | Q39: =#REF! -> #REF! | S39: =#REF! -> #REF! | W39: =#REF! -> #REF! | Y39: =#REF! -> #REF! | AC39: =#REF! -> #REF! | AE39: =#REF! -> #REF! | AG39: =#REF! -> #REF! | AI39: =#REF! -> #REF! | AK39: =#REF! -> #REF! | AM39: =#REF! -> #REF! | AO39: =#REF! -> #REF! | AQ39: =#REF! -> #REF! | AS39: =#REF! -> #REF! | AU39: =#REF! -> #REF! | AW39: =#REF! -> #REF! | AY39: =#REF! -> #REF!
A40: 1.1 | B40: Marketing Expenses
B41: General Marketing Expenses | F41: 0.01 | G41: of NDV | I41: =$F$41*I61 -> 1764000 | K41: =$F$41*K61 -> #REF! | M41: =$F$41*M61 -> 0 | O41: =$F$41*O61 -> 0 | Q41: =$F$41*Q61 -> 0 | S41: =$F$41*S61 -> 0 | W41: =$F$41*W61 -> 0 | Y41: =$F$41*Y61 -> 0 | AC41: =$F$41*AC61 -> 0 | AE41: =$F$41*AE61 -> 0 | AG41: =$F$41*AG61 -> 0 | AI41: =$F$41*AI61 -> 0 | AK41: =$F$41*AK61 -> 0 | AM41: =$F$41*AM61 -> 0 | AO41: =$F$41*AO61 -> 0 | AQ41: =$F$41*AQ61 -> 0 | AS41: =$F$41*AS61 -> 0 | AU41: =$F$41*AU61 -> 0 | AW41: =$F$41*AW61 -> 0 | AY41: =SUM(I41:AW41) -> #REF!
B42: Architectural Models | AY42: =SUM(I42:AW42) -> 0
B43: Market Research | AY43: =SUM(I43:AW43) -> 0
B44: Construction Sales Gallery | AY44: =SUM(I44:AW44) -> 0
B45: Yenom Final Acc SG,G/Houseinc landscape | D45: =2400000+2600000 -> 5000000 | AY45: =SUM(I45:AW45) -> 0
...

Sheet Cashflow
A1: BRDB LAND — MONTHLY CASHFLOW MODEL (RM'000)
A2: All values RM'000 | Blue = inputs | Black = formulas | Green = linked from Feasibility Study
C3: Year 1 | O3: Year 2 | AA3: Year 3 | AM3: Year 4 | AY3: Year 5
A4: DESCRIPTION | B4: BASIS / TOTAL (RM'000) | C4: Jan '26 | D4: Feb '26 | E4: Mar '26 | F4: Apr '26 | G4: May '26 | H4: Jun '26 | I4: Jul '26 | J4: Aug '26 | K4: Sep '26 | L4: Oct '26 | M4: Nov '26 | N4: Dec '26 | O4: Jan '27 | P4: Feb '27 | Q4: Mar '27 | R4: Apr '27 | S4: May '27 | T4: Jun '27 | U4: Jul '27 | V4: Aug '27 | W4: Sep '27 | X4: Oct '27 | Y4: Nov '27 | Z4: Dec '27 | AA4: Jan '28 | AB4: Feb '28 | AC4: Mar '28 | AD4: Apr '28 | AE4: May '28 | AF4: Jun '28 | AG4: Jul '28 | AH4: Aug '28 | AI4: Sep '28 | AJ4: Oct '28 | AK4: Nov '28 | AL4: Dec '28 | AM4: Jan '29 | AN4: Feb '29 | AO4: Mar '29 | AP4: Apr '29 | AQ4: May '29 | AR4: Jun '29 | AS4: Jul '29 | AT4: Aug '29 | AU4: Sep '29 | AV4: Oct '29 | AW4: Nov '29 | AX4: Dec '29 | AY4: Jan '30 | AZ4: Feb '30 | BA4: Mar '30 | BB4: Apr '30 | BC4: May '30 | BD4: Jun '30 | BE4: Jul '30 | BF4: Aug '30 | BG4: Sep '30 | BH4: Oct '30 | BI4: Nov '30 | BJ4: Dec '30 | BK4: TOTAL
A5: Start date | C5: 46023 | D5: 46054 | E5: 46082 | F5: 46113 | G5: 46143 | H5: 46174 | I5: 46204 | J5: 46235 | K5: 46266 | L5: 46296 | M5: 46327 | N5: 46357 | O5: 46388 | P5: 46419 | Q5: 46447 | R5: 46478 | S5: 46508 | T5: 46539 | U5: 46569 | V5: 46600 | W5: 46631 | X5: 46661 | Y5: 46692 | Z5: 46722 | AA5: 46753 | AB5: 46784 | AC5: 46813 | AD5: 46844 | AE5: 46874 | AF5: 46905 | AG5: 46935 | AH5: 46966 | AI5: 46997 | AJ5: 47027 | AK5: 47058 | AL5: 47088 | AM5: 47119 | AN5: 47150 | AO5: 47178 | AP5: 47209 | AQ5: 47239 | AR5: 47270 | AS5: 47300 | AT5: 47331 | AU5: 47362 | AV5: 47392 | AW5: 47423 | AX5: 47453 | AY5: 47484 | AZ5: 47515 | BA5: 47543 | BB5: 47574 | BC5: 47604 | BD5: 47635 | BE5: 47665 | BF5: 47696 | BG5: 47727 | BH5: 47757 | BI5: 47788 | BJ5: 47818
A7: A. PROJECT ASSUMPTIONS
A8: Project name | B8: BRDB Land Development
A9: Development period (years) | B9: 5
A10: Project start | B10: January 2026
A11: Total GDV (RM'000) | B11: ='Feasibility Study'!AY38/1000 -> #REF!
A12: Total NDV (RM'000) | B12: ='Feasibility Study'!AY61/1000 -> #REF!
A13: Total GDC (RM'000) | B13: ='Feasibility Study'!AY148/1000 -> #REF!
A14: Total NDP (RM'000) | B14: ='Feasibility Study'!AY161/1000 -> #REF!
A15: Land cost (RM'000) | B15: ='Feasibility Study'!AY72/1000 -> 12797.928
A16: Construction cost (RM'000) | B16: ='Feasibility Study'!AY79/1000 -> #REF!
A17: Annual interest rate | B17: 0.0455
A18: Target IRR (hurdle) | B18: 0.16
A20: B. MONTHLY SALES ABSORPTION SCHEDULE (% of NDV collected per month)
A21: S-curve absorption — slow launch M1–M6, peak Y2–Y3, tail-off Y4–Y5. Edit % in blue.
A22: Phase | B22: Type | C22: Jan | D22: Feb | E22: Mar | F22: Apr | G22: May | H22: Jun | I22: Jul | J22: Aug | K22: Sep | L22: Oct | M22: Nov | N22: Dec | O22: Jan | P22: Feb | Q22: Mar | R22: Apr | S22: May | T22: Jun | U22: Jul | V22: Aug | W22: Sep | X22: Oct | Y22: Nov | Z22: Dec | AA22: Jan | AB22: Feb | AC22: Mar | AD22: Apr | AE22: May | AF22: Jun | AG22: Jul | AH22: Aug | AI22: Sep | AJ22: Oct | AK22: Nov | AL22: Dec | AM22: Jan | AN22: Feb | AO22: Mar | AP22: Apr | AQ22: May | AR22: Jun | AS22: Jul | AT22: Aug | AU22: Sep | AV22: Oct | AW22: Nov | AX22: Dec | AY22: Jan | AZ22: Feb | BA22: Mar | BB22: Apr | BC22: May | BD22: Jun | BE22: Jul | BF22: Aug | BG22: Sep | BH22: Oct | BI22: Nov | BJ22: Dec | BK22: Total %
A23: Ph 1a | B23: residential | C23: 0.01 | D23: 0.01 | E23: 0.01 | F23: 0.02 | G23: 0.02 | H23: 0.02 | I23: 0.02 | J23: 0.02 | K23: 0.02 | L23: 0.03 | M23: 0.03 | N23: 0.03 | O23: 0.03 | P23: 0.03 | Q23: 0.03 | R23: 0.04 | S23: 0.04 | T23: 0.04 | U23: 0.04 | V23: 0.04 | W23: 0.04 | X23: 0.04 | Y23: 0.03 | Z23: 0.03 | AA23: 0.03 | AB23: 0.03 | AC23: 0.03 | AD23: 0.02 | AE23: 0.02 | AF23: 0.02 | AG23: 0.02 | AH23: 0.02 | AI23: 0.02 | AJ23: 0.02 | AK23: 0.02 | AL23: 0.02 | AM23: 0.01 | AN23: 0.01 | AO23: 0.01 | AP23: 0.01 | AQ23: 0.01 | AR23: 0.01 | AS23: 0 | AT23: 0 | AU23: 0 | AV23: 0 | AW23: 0 | AX23: 0 | AY23: 0 | AZ23: 0 | BA23: 0 | BB23: 0 | BC23: 0 | BD23: 0 | BE23: 0 | BF23: 0 | BG23: 0 | BH23: 0 | BI23: 0 | BJ23: 0 | BK23: =SUM(C23:BJ23) -> 1
A24: Ph 1b | B24: residential | C24: 0.01 | D24: 0.01 | E24: 0.01 | F24: 0.02 | G24: 0.02 | H24: 0.02 | I24: 0.02 | J24: 0.02 | K24: 0.02 | L24: 0.03 | M24: 0.03 | N24: 0.03 | O24: 0.03 | P24: 0.03 | Q24: 0.03 | R24: 0.04 | S24: 0.04 | T24: 0.04 | U24: 0.04 | V24: 0.04 | W24: 0.04 | X24: 0.04 | Y24: 0.03 | Z24: 0.03 | AA24: 0.03 | AB24: 0.03 | AC24: 0.03 | AD24: 0.02 | AE24: 0.02 | AF24: 0.02 | AG24: 0.02 | AH24: 0.02 | AI24: 0.02 | AJ24: 0.02 | AK24: 0.02 | AL24: 0.02 | AM24: 0.01 | AN24: 0.01 | AO24: 0.01 | AP24: 0.01 | AQ24: 0.01 | AR24: 0.01 | AS24: 0 | AT24: 0 | AU24: 0 | AV24: 0 | AW24: 0 | AX24: 0 | AY24: 0 | AZ24: 0 | BA24: 0 | BB24: 0 | BC24: 0 | BD24: 0 | BE24: 0 | BF24: 0 | BG24: 0 | BH24: 0 | BI24: 0 | BJ24: 0 | BK24: =SUM(C24:BJ24) -> 1
A25: Ph 1c | B25: affordable | C25: 0.02 | D25: 0.02 | E25: 0.03 | F25: 0.03 | G25: 0.03 | H25: 0.05 | I25: 0.04 | J25: 0.04 | K25: 0.04 | L25: 0.04 | M25: 0.04 | N25: 0.04 | O25: 0.04 | P25: 0.04 | Q25: 0.04 | R25: 0.04 | S25: 0.03 | T25: 0.03 | U25: 0.03 | V25: 0.03 | W25: 0.03 | X25: 0.03 | Y25: 0.03 | Z25: 0.03 | AA25: 0.02 | AB25: 0.02 | AC25: 0.02 | AD25: 0.02 | AE25: 0.02 | AF25: 0.02 | AG25: 0.01 | AH25: 0.01 | AI25: 0.01 | AJ25: 0.01 | AK25: 0.01 | AL25: 0.01 | AM25: 0 | AN25: 0 | AO25: 0 | AP25: 0 | AQ25: 0 | AR25: 0 | AS25: 0 | AT25: 0 | AU25: 0 | AV25: 0 | AW25: 0 | AX25: 0 | AY25: 0 | AZ25: 0 | BA25: 0 | BB25: 0 | BC25: 0 | BD25: 0 | BE25: 0 | BF25: 0 | BG25: 0 | BH25: 0 | BI25: 0 | BJ25: 0 | BK25: =SUM(C25:BJ25) -> 1
A26: Ph 1d | B26: affordable | C26: 0.02 | D26: 0.02 | E26: 0.03 | F26: 0.03 | G26: 0.03 | H26: 0.05 | I26: 0.04 | J26: 0.04 | K26: 0.04 | L26: 0.04 | M26: 0.04 | N26: 0.04 | O26: 0.04 | P26: 0.04 | Q26: 0.04 | R26: 0.04 | S26: 0.03 | T26: 0.03 | U26: 0.03 | V26: 0.03 | W26: 0.03 | X26: 0.03 | Y26: 0.03 | Z26: 0.03 | AA26: 0.02 | AB26: 0.02 | AC26: 0.02 | AD26: 0.02 | AE26: 0.02 | AF26: 0.02 | AG26: 0.01 | AH26: 0.01 | AI26: 0.01 | AJ26: 0.01 | AK26: 0.01 | AL26: 0.01 | AM26: 0 | AN26: 0 | AO26: 0 | AP26: 0 | AQ26: 0 | AR26: 0 | AS26: 0 | AT26: 0 | AU26: 0 | AV26: 0 | AW26: 0 | AX26: 0 | AY26: 0 | AZ26: 0 | BA26: 0 | BB26: 0 | BC26: 0 | BD26: 0 | BE26: 0 | BF26: 0 | BG26: 0 | BH26: 0 | BI26: 0 | BJ26: 0 | BK26: =SUM(C26:BJ26) -> 1
A27: Ph 1e | B27: commercial | C27: 0.02 | D27: 0.03 | E27: 0.03 | F27: 0.04 | G27: 0.04 | H27: 0.04 | I27: 0.04 | J27: 0.04 | K27: 0.05 | L27: 0.05 | M27: 0.05 | N27: 0.05 | O27: 0.05 | P27: 0.05 | Q27: 0.05 | R27: 0.05 | S27: 0.04 | T27: 0.04 | U27: 0.04 | V27: 0.04 | W27: 0.03 | X27: 0.03 | Y27: 0.02 | Z27: 0.02 | AA27: 0.01 | AB27: 0.01 | AC27: 0.01 | AD27: 0.01 | AE27: 0.01 | AF27: 0.01 | AG27: 0 | AH27: 0 | AI27: 0 | AJ27: 0 | AK27: 0 | AL27: 0 | AM27: 0 | AN27: 0 | AO27: 0 | AP27: 0 | AQ27: 0 | AR27: 0 | AS27: 0 | AT27: 0 | AU27: 0 | AV27: 0 | AW27: 0 | AX27: 0 | AY27: 0 | AZ27: 0 | BA27: 0 | BB27: 0 | BC27: 0 | BD27: 0 | BE27: 0 | BF27: 0 | BG27: 0 | BH27: 0 | BI27: 0 | BJ27: 0 | BK27: =SUM(C27:BJ27) -> 1
A28: Ph 1f | B28: residential | C28: 0.01 | D28: 0.01 | E28: 0.01 | F28: 0.02 | G28: 0.02 | H28: 0.02 | I28: 0.02 | J28: 0.02 | K28: 0.02 | L28: 0.03 | M28: 0.03 | N28: 0.03 | O28: 0.03 | P28: 0.03 | Q28: 0.03 | R28: 0.04 | S28: 0.04 | T28: 0.04 | U28: 0.04 | V28: 0.04 | W28: 0.04 | X28: 0.04 | Y28: 0.03 | Z28: 0.03 | AA28: 0.03 | AB28: 0.03 | AC28: 0.03 | AD28: 0.02 | AE28: 0.02 | AF28: 0.02 | AG28: 0.02 | AH28: 0.02 | AI28: 0.02 | AJ28: 0.02 | AK28: 0.02 | AL28: 0.02 | AM28: 0.01 | AN28: 0.01 | AO28: 0.01 | AP28: 0.01 | AQ28: 0.01 | AR28: 0.01 | AS28: 0 | AT28: 0 | AU28: 0 | AV28: 0 | AW28: 0 | AX28: 0 | AY28: 0 | AZ28: 0 | BA28: 0 | BB28: 0 | BC28: 0 | BD28: 0 | BE28: 0 | BF28: 0 | BG28: 0 | BH28: 0 | BI28: 0 | BJ28: 0 | BK28: =SUM(C28:BJ28) -> 1
A29: Ph 1g | B29: commercial | C29: 0.02 | D29: 0.03 | E29: 0.03 | F29: 0.04 | G29: 0.04 | H29: 0.04 | I29: 0.04 | J29: 0.04 | K29: 0.05 | L29: 0.05 | M29: 0.05 | N29: 0.05 | O29: 0.05 | P29: 0.05 | Q29: 0.05 | R29: 0.05 | S29: 0.04 | T29: 0.04 | U29: 0.04 | V29: 0.04 | W29: 0.03 | X29: 0.03 | Y29: 0.02 | Z29: 0.02 | AA29: 0.01 | AB29: 0.01 | AC29: 0.01 | AD29: 0.01 | AE29: 0.01 | AF29: 0.01 | AG29: 0 | AH29: 0 | AI29: 0 | AJ29: 0 | AK29: 0 | AL29: 0 | AM29: 0 | AN29: 0 | AO29: 0 | AP29: 0 | AQ29: 0 | AR29: 0 | AS29: 0 | AT29: 0 | AU29: 0 | AV29: 0 | AW29: 0 | AX29: 0 | AY29: 0 | AZ29: 0 | BA29: 0 | BB29: 0 | BC29: 0 | BD29: 0 | BE29: 0 | BF29: 0 | BG29: 0 | BH29: 0 | BI29: 0 | BJ29: 0 | BK29: =SUM(C29:BJ29) -> 1
A30: Ph 1h | B30: commercial | C30: 0.02 | D30: 0.03 | E30: 0.03 | F30: 0.04 | G30: 0.04 | H30: 0.04 | I30: 0.04 | J30: 0.04 | K30: 0.05 | L30: 0.05 | M30: 0.05 | N30: 0.05 | O30: 0.05 | P30: 0.05 | Q30: 0.05 | R30: 0.05 | S30: 0.04 | T30: 0.04 | U30: 0.04 | V30: 0.04 | W30: 0.03 | X30: 0.03 | Y30: 0.02 | Z30: 0.02 | AA30: 0.01 | AB30: 0.01 | AC30: 0.01 | AD30: 0.01 | AE30: 0.01 | AF30: 0.01 | AG30: 0 | AH30: 0 | AI30: 0 | AJ30: 0 | AK30: 0 | AL30: 0 | AM30: 0 | AN30: 0 | AO30: 0 | AP30: 0 | AQ30: 0 | AR30: 0 | AS30: 0 | AT30: 0 | AU30: 0 | AV30: 0 | AW30: 0 | AX30: 0 | AY30: 0 | AZ30: 0 | BA30: 0 | BB30: 0 | BC30: 0 | BD30: 0 | BE30: 0 | BF30: 0 | BG30: 0 | BH30: 0 | BI30: 0 | BJ30: 0 | BK30: =SUM(C30:BJ30) -> 1
A31: Ph 2a | B31: residential | C31: 0.01 | D31: 0.01 | E31: 0.01 | F31: 0.02 | G31: 0.02 | H31: 0.02 | I31: 0.02 | J31: 0.02 | K31: 0.02 | L31: 0.03 | M31: 0.03 | N31: 0.03 | O31: 0.03 | P31: 0.03 | Q31: 0.03 | R31: 0.04 | S31: 0.04 | T31: 0.04 | U31: 0.04 | V31: 0.04 | W31: 0.04 | X31: 0.04 | Y31: 0.03 | Z31: 0.03 | AA31: 0.03 | AB31: 0.03 | AC31: 0.03 | AD31: 0.02 | AE31: 0.02 | AF31: 0.02 | AG31: 0.02 | AH31: 0.02 | AI31: 0.02 | AJ31: 0.02 | AK31: 0.02 | AL31: 0.02 | AM31: 0.01 | AN31: 0.01 | AO31: 0.01 | AP31: 0.01 | AQ31: 0.01 | AR31: 0.01 | AS31: 0 | AT31: 0 | AU31: 0 | AV31: 0 | AW31: 0 | AX31: 0 | AY31: 0 | AZ31: 0 | BA31: 0 | BB31: 0 | BC31: 0 | BD31: 0 | BE31: 0 | BF31: 0 | BG31: 0 | BH31: 0 | BI31: 0 | BJ31: 0 | BK31: =SUM(C31:BJ31) -> 1
A32: Ph 2b | B32: residential | C32: 0.01 | D32: 0.01 | E32: 0.01 | F32: 0.02 | G32: 0.02 | H32: 0.02 | I32: 0.02 | J32: 0.02 | K32: 0.02 | L32: 0.03 | M32: 0.03 | N32: 0.03 | O32: 0.03 | P32: 0.03 | Q32: 0.03 | R32: 0.04 | S32: 0.04 | T32: 0.04 | U32: 0.04 | V32: 0.04 | W32: 0.04 | X32: 0.04 | Y32: 0.03 | Z32: 0.03 | AA32: 0.03 | AB32: 0.03 | AC32: 0.03 | AD32: 0.02 | AE32: 0.02 | AF32: 0.02 | AG32: 0.02 | AH32: 0.02 | AI32: 0.02 | AJ32: 0.02 | AK32: 0.02 | AL32: 0.02 | AM32: 0.01 | AN32: 0.01 | AO32: 0.01 | AP32: 0.01 | AQ32: 0.01 | AR32: 0.01 | AS32: 0 | AT32: 0 | AU32: 0 | AV32: 0 | AW32: 0 | AX32: 0 | AY32: 0 | AZ32: 0 | BA32: 0 | BB32: 0 | BC32: 0 | BD32: 0 | BE32: 0 | BF32: 0 | BG32: 0 | BH32: 0 | BI32: 0 | BJ32: 0 | BK32: =SUM(C32:BJ32) -> 1
A33: Ph 2c | B33: residential | C33: 0.01 | D33: 0.01 | E33: 0.01 | F33: 0.02 | G33: 0.02 | H33: 0.02 | I33: 0.02 | J33: 0.02 | K33: 0.02 | L33: 0.03 | M33: 0.03 | N33: 0.03 | O33: 0.03 | P33: 0.03 | Q33: 0.03 | R33: 0.04 | S33: 0.04 | T33: 0.04 | U33: 0.04 | V33: 0.04 | W33: 0.04 | X33: 0.04 | Y33: 0.03 | Z33: 0.03 | AA33: 0.03 | AB33: 0.03 | AC33: 0.03 | AD33: 0.02 | AE33: 0.02 | AF33: 0.02 | AG33: 0.02 | AH33: 0.02 | AI33: 0.02 | AJ33: 0.02 | AK33: 0.02 | AL33: 0.02 | AM33: 0.01 | AN33: 0.01 | AO33: 0.01 | AP33: 0.01 | AQ33: 0.01 | AR33: 0.01 | AS33: 0 | AT33: 0 | AU33: 0 | AV33: 0 | AW33: 0 | AX33: 0 | AY33: 0 | AZ33: 0 | BA33: 0 | BB33: 0 | BC33: 0 | BD33: 0 | BE33: 0 | BF33: 0 | BG33: 0 | BH33: 0 | BI33: 0 | BJ33: 0 | BK33: =SUM(C33:BJ33) -> 1
A34: Ph 2d | B34: residential | C34: 0.01 | D34: 0.01 | E34: 0.01 | F34: 0.02 | G34: 0.02 | H34: 0.02 | I34: 0.02 | J34: 0.02 | K34: 0.02 | L34: 0.03 | M34: 0.03 | N34: 0.03 | O34: 0.03 | P34: 0.03 | Q34: 0.03 | R34: 0.04 | S34: 0.04 | T34: 0.04 | U34: 0.04 | V34: 0.04 | W34: 0.04 | X34: 0.04 | Y34: 0.03 | Z34: 0.03 | AA34: 0.03 | AB34: 0.03 | AC34: 0.03 | AD34: 0.02 | AE34: 0.02 | AF34: 0.02 | AG34: 0.02 | AH34: 0.02 | AI34: 0.02 | AJ34: 0.02 | AK34: 0.02 | AL34: 0.02 | AM34: 0.01 | AN34: 0.01 | AO34: 0.01 | AP34: 0.01 | AQ34: 0.01 | AR34: 0.01 | AS34: 0 | AT34: 0 | AU34: 0 | AV34: 0 | AW34: 0 | AX34: 0 | AY34: 0 | AZ34: 0 | BA34: 0 | BB34: 0 | BC34: 0 | BD34: 0 | BE34: 0 | BF34: 0 | BG34: 0 | BH34: 0 | BI34: 0 | BJ34: 0 | BK34: =SUM(C34:BJ34) -> 1
... A40: Ph 2j | B40: commercial | C40: 0.02 | D40: 0.03 | E40: 0.03 | F40: 0.04 | G40: 0.04 | H40: 0.04 | I40: 0.04 | J40: 0.04 | K40: 0.05 | L40: 0.05 | M40: 0.05 | N40: 0.05 | O40: 0.05 | P40: 0.05 | Q40: 0.05 | R40: 0.05 | S40: 0.04 | T40: 0.04 | U40: 0.04 | V40: 0.04 | W40: 0.03 | X40: 0.03 | Y40: 0.02 | Z40: 0.02 | AA40: 0.01 | AB40: 0.01 | AC40: 0.01 | AD40: 0.01 | AE40: 0.01 | AF40: 0.01 | AG40: 0 | AH40: 0 | AI40: 0 | AJ40: 0 | AK40: 0 | AL40: 0 | AM40: 0 | AN40: 0 | AO40: 0 | AP40: 0 | AQ40: 0 | AR40: 0 | AS40: 0 | AT40: 0 | AU40: 0 | AV40: 0 | AW40: 0 | AX40: 0 | AY40: 0 | AZ40: 0 | BA40: 0 | BB40: 0 | BC40: 0 | BD40: 0 | BE40: 0 | BF40: 0 | BG40: 0 | BH40: 0 | BI40: 0 | BJ40: 0 | BK40: =SUM(C40:BJ40) -> 1
A42: C. SALES RECEIPTS (RM'000) — NDV × Monthly Absorption %
A43: Phase | B43: NDV (RM'000) | C43: Jan | D43: Feb | E43: Mar | F43: Apr | G43: May | H43: Jun | I43: Jul | J43: Aug | K43: Sep | L43: Oct | M43: Nov | N43: Dec | O43: Jan | P43: Feb | Q43: Mar | R43: Apr | S43: May | T43: Jun | U43: Jul | V43: Aug | W43: Sep | X43: Oct | Y43: Nov | Z43: Dec | AA43: Jan | AB43: Feb | AC43: Mar | AD43: Apr | AE43: May | AF43: Jun | AG43: Jul | AH43: Aug | AI43: Sep | AJ43: Oct | AK43: Nov | AL43: Dec | AM43: Jan | AN43: Feb | AO43: Mar | AP43: Apr | AQ43: May | AR43: Jun | AS43: Jul | AT43: Aug | AU43: Sep | AV43: Oct | AW43: Nov | AX43: Dec | AY43: Jan | AZ43: Feb | BA43: Mar | BB43: Apr | BC43: May | BD43: Jun | BE43: Jul | BF43: Aug | BG43: Sep | BH43: Oct | BI43: Nov | BJ43: Dec | BK43: Total
A44: Ph 1a | B44: ='Feasibility Study'!I61/1000 -> 176400 | C44: =IF($B$44=0,0,$B$44*C23) -> 1764 | D44: =IF($B$44=0,0,$B$44*D23) -> 1764 | E44: =IF($B$44=0,0,$B$44*E23) -> 1764 | F44: =IF($B$44=0,0,$B$44*F23) -> 3528 | G44: =IF($B$44=0,0,$B$44*G23) -> 3528 | H44: =IF($B$44=0,0,$B$44*H23) -> 3528 | I44: =IF($B$44=0,0,$B$44*I23) -> 3528 | J44: =IF($B$44=0,0,$B$44*J23) -> 3528 | ... BJ44: =IF($B$44=0,0,$B$44*BJ23) -> 0 | BK44: =SUM(C44:BJ44) -> 176400
A45: Ph 1b | B45: ='Feasibility Study'!K61/1000 -> #REF! | C45: =IF($B$45=0,0,$B$45*C24) -> #REF! | D45: =IF($B$45=0,0,$B$45*D24) -> #REF! | E45: =IF($B$45=0,0,$B$45*E24) -> #REF! | F45: =IF($B$45=0,0,$B$45*F24) -> #REF! | G45: =IF($B$45=0,0,$B$45*G24) -> #REF! | H45: =IF($B$45=0,0,$B$45*H24) -> #REF! | I45: =IF($B$45=0,0,$B$45*I24) -> #REF! | J45: =IF($B$45=0,0,$B$45*J24) -> #REF! | ... BJ45: =IF($B$45=0,0,$B$45*BJ24) -> #REF! | BK45: =SUM(C45:BJ45) -> #REF!
A46: Ph 1c | B46: ='Feasibility Study'!M61/1000 -> 0 | C46: =IF($B$46=0,0,$B$46*C25) -> 0 | D46: =IF($B$46=0,0,$B$46*D25) -> 0 | E46: =IF($B$46=0,0,$B$46*E25) -> 0 | F46: =IF($B$46=0,0,$B$46*F25) -> 0 | G46: =IF($B$46=0,0,$B$46*G25) -> 0 | H46: =IF($B$46=0,0,$B$46*H25) -> 0 | I46: =IF($B$46=0,0,$B$46*I25) -> 0 | J46: =IF($B$46=0,0,$B$46*J25) -> 0 | ... BJ46: =IF($B$46=0,0,$B$46*BJ25) -> 0 | BK46: =SUM(C46:BJ46) -> 0
A47: Ph 1d | B47: ='Feasibility Study'!O61/1000 -> 0 | C47: =IF($B$47=0,0,$B$47*C26) -> 0 | D47: =IF($B$47=0,0,$B$47*D26) -> 0 | E47: =IF($B$47=0,0,$B$47*E26) -> 0 | F47: =IF($B$47=0,0,$B$47*F26) -> 0 | G47: =IF($B$47=0,0,$B$47*G26) -> 0 | H47: =IF($B$47=0,0,$B$47*H26) -> 0 | I47: =IF($B$47=0,0,$B$47*I26) -> 0 | J47: =IF($B$47=0,0,$B$47*J26) -> 0 | ... BJ47: =IF($B$47=0,0,$B$47*BJ26) -> 0 | BK47: =SUM(C47:BJ47) -> 0
A48: Ph 1e | B48: ='Feasibility Study'!Q61/1000 -> 0 | C48: =IF($B$48=0,0,$B$48*C27) -> 0 | D48: =IF($B$48=0,0,$B$48*D27) -> 0 | E48: =IF($B$48=0,0,$B$48*E27) -> 0 | F48: =IF($B$48=0,0,$B$48*F27) -> 0 | G48: =IF($B$48=0,0,$B$48*G27) -> 0 | H48: =IF($B$48=0,0,$B$48*H27) -> 0 | I48: =IF($B$48=0,0,$B$48*I27) -> 0 | J48: =IF($B$48=0,0,$B$48*J27) -> 0 | ... BJ48: =IF($B$48=0,0,$B$48*BJ27) -> 0 | BK48: =SUM(C48:BJ48) -> 0
...

Sheet Returns
A1: BRDB LAND — RETURNS & SENSITIVITY ANALYSIS
A2: All values RM'000 | XIRR on 60 monthly cashflows | Blue = inputs | Green = linked from other sheets
A4: A. PROJECT SUMMARY
A5: Total GDV (RM'000) | B5: ='Feasibility Study'!AY38/1000 -> #REF!
A6: Total NDV (RM'000) | B6: ='Feasibility Study'!AY61/1000 -> #REF!
A7: Gross dev cost — GDC (RM'000) | B7: ='Feasibility Study'!AY148/1000 -> #REF!
A8: Net dev profit — NDP (RM'000) | B8: ='Feasibility Study'!AY161/1000 -> #REF!
A9: Dev margin % on NDV | B9: =IF(B6=0,0,B8/B6) -> #REF!
A10: Land cost (RM'000) | B10: ='Feasibility Study'!AY72/1000 -> 12797.928
A11: Construction cost (RM'000) | B11: ='Feasibility Study'!AY79/1000 -> #REF!
A12: Peak equity exposure (RM'000) | B12: =Cashflow!BK98 -> #REF!
A13: Development period (years) | B13: =Cashflow!B8 -> BRDB Land Development
A16: B. EQUITY CASHFLOW SCHEDULE — Input for XIRR
A17: Equity invested = outflows up to peak; equity repaid = inflows after peak. Dates set to quarterly from project start.
A18: Quarter | B18: Date | C18: Net CF (RM'000) | D18: Cumulative (RM'000)
A19: Y1 M01 | B19: 46023 | C19: =Cashflow!C97 -> #REF! | D19: =Cashflow!C98 -> #REF!
A20: Y1 M02 | B20: 46054 | C20: =Cashflow!D97 -> #REF! | D20: =Cashflow!D98 -> #REF!
A21: Y1 M03 | B21: 46082 | C21: =Cashflow!E97 -> #REF! | D21: =Cashflow!E98 -> #REF!
A22: Y1 M04 | B22: 46113 | C22: =Cashflow!F97 -> #REF! | D22: =Cashflow!F98 -> #REF!
A23: Y1 M05 | B23: 46143 | C23: =Cashflow!G97 -> #REF! | D23: =Cashflow!G98 -> #REF!
A24: Y1 M06 | B24: 46174 | C24: =Cashflow!H97 -> #REF! | D24: =Cashflow!H98 -> #REF!
A25: Y1 M07 | B25: 46204 | C25: =Cashflow!I97 -> #REF! | D25: =Cashflow!I98 -> #REF!
A26: Y1 M08 | B26: 46235 | C26: =Cashflow!J97 -> #REF! | D26: =Cashflow!J98 -> #REF!
A27: Y1 M09 | B27: 46266 | C27: =Cashflow!K97 -> #REF! | D27: =Cashflow!K98 -> #REF!
A28: Y1 M10 | B28: 46296 | C28: =Cashflow!L97 -> #REF! | D28: =Cashflow!L98 -> #REF!
A29: Y1 M11 | B29: 46327 | C29: =Cashflow!M97 -> #REF! | D29: =Cashflow!M98 -> #REF!
A30: Y1 M12 | B30: 46357 | C30: =Cashflow!N97 -> #REF! | D30: =Cashflow!N98 -> #REF!
A31: Y2 M01 | B31: 46388 | C31: =Cashflow!O97 -> #REF! | D31: =Cashflow!O98 -> #REF!
A32: Y2 M02 | B32: 46419 | C32: =Cashflow!P97 -> #REF! | D32: =Cashflow!P98 -> #REF!
A33: Y2 M03 | B33: 46447 | C33: =Cashflow!Q97 -> #REF! | D33: =Cashflow!Q98 -> #REF!
A34: Y2 M04 | B34: 46478 | C34: =Cashflow!R97 -> #REF! | D34: =Cashflow!R98 -> #REF!
A35: Y2 M05 | B35: 46508 | C35: =Cashflow!S97 -> #REF! | D35: =Cashflow!S98 -> #REF!
A36: Y2 M06 | B36: 46539 | C36: =Cashflow!T97 -> #REF! | D36: =Cashflow!T98 -> #REF!
A37: Y2 M07 | B37: 46569 | C37: =Cashflow!U97 -> #REF! | D37: =Cashflow!U98 -> #REF!
A38: Y2 M08 | B38: 46600 | C38: =Cashflow!V97 -> #REF! | D38: =Cashflow!V98 -> #REF!
A39: Y2 M09 | B39: 46631 | C39: =Cashflow!W97 -> #REF! | D39: =Cashflow!W98 -> #REF!
A40: Y2 M10
A41: Y2 M11 | B41: 46692 | C41: =Cashflow!Y97 -> #REF! | D41: =Cashflow!Y98 -> #REF!
A42: Y2 M12 | B42: 46722 | C42: =Cashflow!Z97 -> #REF! | D42: =Cashflow!Z98 -> #REF!
A43: Y3 M01 | B43: 46753 | C43: =Cashflow!AA97 -> #REF! | D43: =Cashflow!AA98 -> #REF!
...

Sheet IRR & Sensitivity
A1: BRDB LAND — IRR, NPV & SENSITIVITY ANALYSIS
A2: XIRR on 60 monthly cashflows | NPV @ 3 hurdle rates | Colour-coded sensitivity matrices | Land cost breakeven | Blue = inputs changeable by user
A4: A. ASSUMPTIONS & INPUTS | D4: C. SENSITIVITY — PROJECT IRR (%) vs ASP × ABSORPTION | M4: E. SENSITIVITY — IRR (%) vs CONSTRUCTION COST × ASP
A5: Base ASP (RM psf) | B5: 680 | D5: IRR scales with ASP (revenue) and absorption rate. Yellow = base case. Green ≥ hurdle. Red < hurdle. | M5: Construction cost deviation vs ASP deviation. Base: RM 280 psf build cost, RM 680 psf ASP.
A6: Base absorption rate | B6: 0.8 | D6: Absorption ↓ ASP → | E6: RM 476 −30% | F6: RM 544 −20% | G6: RM 612 −10% | H6: RM 680 Base | I6: RM 748 +10% | J6: RM 816 +20% | K6: RM 884 +30% | M6: Constr cost ↓ ASP → | N6: RM 476 −30% | O6: RM 544 −20% | P6: RM 612 −10% | Q6: RM 680 Base | R6: RM 748 +10% | S6: RM 816 +20% | T6: RM 884 +30%
A7: Base build cost (RM psf) | B7: 280 | D7: 50% absorption | E7: =IFERROR(Returns!B81*0.7*0.625,0) -> 0 | F7: =IFERROR(Returns!B81*0.8*0.625,0) -> 0 | G7: =IFERROR(Returns!B81*0.9*0.625,0) -> 0 | H7: =IFERROR(Returns!B81*1*0.625,0) -> 0 | I7: =IFERROR(Returns!B81*1.1*0.625,0) -> 0 | J7: =IFERROR(Returns!B81*1.2*0.625,0) -> 0 | K7: =IFERROR(Returns!B81*1.3*0.625,0) -> 0 | M7: CC −30% | N7: =IFERROR(Returns!B81*0.7/0.82,0) -> 0 | O7: =IFERROR(Returns!B81*0.8/0.82,0) -> 0 | P7: =IFERROR(Returns!B81*0.9/0.82,0) -> 0 | Q7: =IFERROR(Returns!B81*1/0.82,0) -> 0 | R7: =IFERROR(Returns!B81*1.1/0.82,0) -> 0 | S7: =IFERROR(Returns!B81*1.2/0.82,0) -> 0 | T7: =IFERROR(Returns!B81*1.3/0.82,0) -> 0
A8: Target hurdle IRR | B8: =Cashflow!B18 -> 0.16 | D8: 65% absorption | E8: =IFERROR(Returns!B81*0.7*0.8125,0) -> 0 | F8: =IFERROR(Returns!B81*0.8*0.8125,0) -> 0 | G8: =IFERROR(Returns!B81*0.9*0.8125,0) -> 0 | H8: =IFERROR(Returns!B81*1*0.8125,0) -> 0 | I8: =IFERROR(Returns!B81*1.1*0.8125,0) -> 0 | J8: =IFERROR(Returns!B81*1.2*0.8125,0) -> 0 | K8: =IFERROR(Returns!B81*1.3*0.8125,0) -> 0 | M8: CC −20% | N8: =IFERROR(Returns!B81*0.7/0.88,0) -> 0 | O8: =IFERROR(Returns!B81*0.8/0.88,0) -> 0 | P8: =IFERROR(Returns!B81*0.9/0.88,0) -> 0 | Q8: =IFERROR(Returns!B81*1/0.88,0) -> 0 | R8: =IFERROR(Returns!B81*1.1/0.88,0) -> 0 | S8: =IFERROR(Returns!B81*1.2/0.88,0) -> 0 | T8: =IFERROR(Returns!B81*1.3/0.88,0) -> 0
A9: Annual interest rate | B9: =Cashflow!B17 -> 0.0455 | D9: 80% absorption | E9: =IFERROR(Returns!B81*0.7*1,0) -> 0 | F9: =IFERROR(Returns!B81*0.8*1,0) -> 0 | G9: =IFERROR(Returns!B81*0.9*1,0) -> 0 | H9: =IFERROR(Returns!B81*1*1,0) -> 0 | I9: =IFERROR(Returns!B81*1.1*1,0) -> 0 | J9: =IFERROR(Returns!B81*1.2*1,0) -> 0 | K9: =IFERROR(Returns!B81*1.3*1,0) -> 0 | M9: CC −10% | N9: =IFERROR(Returns!B81*0.7/0.94,0) -> 0 | O9: =IFERROR(Returns!B81*0.8/0.94,0) -> 0 | P9: =IFERROR(Returns!B81*0.9/0.94,0) -> 0 | Q9: =IFERROR(Returns!B81*1/0.94,0) -> 0 | R9: =IFERROR(Returns!B81*1.1/0.94,0) -> 0 | S9: =IFERROR(Returns!B81*1.2/0.94,0) -> 0 | T9: =IFERROR(Returns!B81*1.3/0.94,0) -> 0
D10: 95% absorption | E10: =IFERROR(Returns!B81*0.7*1.1875,0) -> 0 | F10: =IFERROR(Returns!B81*0.8*1.1875,0) -> 0 | G10: =IFERROR(Returns!B81*0.9*1.1875,0) -> 0 | H10: =IFERROR(Returns!B81*1*1.1875,0) -> 0 | I10: =IFERROR(Returns!B81*1.1*1.1875,0) -> 0 | J10: =IFERROR(Returns!B81*1.2*1.1875,0) -> 0 | K10: =IFERROR(Returns!B81*1.3*1.1875,0) -> 0 | M10: CC Base | N10: =IFERROR(Returns!B81*0.7/1,0) -> 0 | O10: =IFERROR(Returns!B81*0.8/1,0) -> 0 | P10: =IFERROR(Returns!B81*0.9/1,0) -> 0 | Q10: =IFERROR(Returns!B81*1/1,0) -> 0 | R10: =IFERROR(Returns!B81*1.1/1,0) -> 0 | S10: =IFERROR(Returns!B81*1.2/1,0) -> 0 | T10: =IFERROR(Returns!B81*1.3/1,0) -> 0
A11: Total GDV (RM'000) | B11: =Returns!B5 -> #REF! | D11: 110% absorption | E11: =IFERROR(Returns!B81*0.7*1.375,0) -> 0 | F11: =IFERROR(Returns!B81*0.8*1.375,0) -> 0 | G11: =IFERROR(Returns!B81*0.9*1.375,0) -> 0 | H11: =IFERROR(Returns!B81*1*1.375,0) -> 0 | I11: =IFERROR(Returns!B81*1.1*1.375,0) -> 0 | J11: =IFERROR(Returns!B81*1.2*1.375,0) -> 0 | K11: =IFERROR(Returns!B81*1.3*1.375,0) -> 0 | M11: CC +10% | N11: =IFERROR(Returns!B81*0.7/1.06,0) -> 0 | O11: =IFERROR(Returns!B81*0.8/1.06,0) -> 0 | P11: =IFERROR(Returns!B81*0.9/1.06,0) -> 0 | Q11: =IFERROR(Returns!B81*1/1.06,0) -> 0 | R11: =IFERROR(Returns!B81*1.1/1.06,0) -> 0 | S11: =IFERROR(Returns!B81*1.2/1.06,0) -> 0 | T11: =IFERROR(Returns!B81*1.3/1.06,0) -> 0
A12: Total NDV (RM'000) | B12: =Returns!B6 -> #REF! | M12: CC +20% | N12: =IFERROR(Returns!B81*0.7/1.12,0) -> 0 | O12: =IFERROR(Returns!B81*0.8/1.12,0) -> 0 | P12: =IFERROR(Returns!B81*0.9/1.12,0) -> 0 | Q12: =IFERROR(Returns!B81*1/1.12,0) -> 0 | R12: =IFERROR(Returns!B81*1.1/1.12,0) -> 0 | S12: =IFERROR(Returns!B81*1.2/1.12,0) -> 0 | T12: =IFERROR(Returns!B81*1.3/1.12,0) -> 0
A13: Total GDC (RM'000) | B13: =Returns!B7 -> #REF! | D13: D. SENSITIVITY — NDP MARGIN (%) vs ASP × ABSORPTION | M13: CC +30% | N13: =IFERROR(Returns!B81*0.7/1.18,0) -> 0 | O13: =IFERROR(Returns!B81*0.8/1.18,0) -> 0 | P13: =IFERROR(Returns!B81*0.9/1.18,0) -> 0 | Q13: =IFERROR(Returns!B81*1/1.18,0) -> 0 | R13: =IFERROR(Returns!B81*1.1/1.18,0) -> 0 | S13: =IFERROR(Returns!B81*1.2/1.18,0) -> 0 | T13: =IFERROR(Returns!B81*1.3/1.18,0) -> 0
A14: Total NDP (RM'000) | B14: =Returns!B8 -> #REF! | D14: NDP margin = (NDV×ASP×Abs − GDC) / (NDV×ASP×Abs). Green ≥ 25% | Amber 15–25% | Red < 15%
A15: Land cost (RM'000) | B15: =Cashflow!B15 -> 12797.928 | D15: Absorption ↓ ASP → | E15: RM 476 −30% | F15: RM 544 −20% | G15: RM 612 −10% | H15: RM 680 Base | I15: RM 748 +10% | J15: RM 816 +20% | K15: RM 884 +30% | M15: F. MAX LAND COST BREAKEVEN vs ASP (RM'000)
A16: Construction cost (RM'000) | B16: =Cashflow!B16 -> #REF! | D16: 50% absorption | E16: =IFERROR(((Returns!B6*0.7*0.625)-Returns!B7)/(Returns!B6*0.7*0.625),0) -> 0 | F16: =IFERROR(((Returns!B6*0.8*0.625)-Returns!B7)/(Returns!B6*0.8*0.625),0) -> 0 | G16: =IFERROR(((Returns!B6*0.9*0.625)-Returns!B7)/(Returns!B6*0.9*0.625),0) -> 0 | H16: =IFERROR(((Returns!B6*1*0.625)-Returns!B7)/(Returns!B6*1*0.625),0) -> 0 | I16: =IFERROR(((Returns!B6*1.1*0.625)-Returns!B7)/(Returns!B6*1.1*0.625),0) -> 0 | J16: =IFERROR(((Returns!B6*1.2*0.625)-Returns!B7)/(Returns!B6*1.2*0.625),0) -> 0 | K16: =IFERROR(((Returns!B6*1.3*0.625)-Returns!B7)/(Returns!B6*1.3*0.625),0) -> 0 | M16: Max land cost payable to still achieve target IRR (16%). Useful for land price negotiation.
A17: Peak equity exposure (RM'000) | B17: =Returns!B12 -> #REF! | D17: 65% absorption | E17: =IFERROR(((Returns!B6*0.7*0.8125)-Returns!B7)/(Returns!B6*0.7*0.8125),0) -> 0 | F17: =IFERROR(((Returns!B6*0.8*0.8125)-Returns!B7)/(Returns!B6*0.8*0.8125),0) -> 0 | G17: =IFERROR(((Returns!B6*0.9*0.8125)-Returns!B7)/(Returns!B6*0.9*0.8125),0) -> 0 | H17: =IFERROR(((Returns!B6*1*0.8125)-Returns!B7)/(Returns!B6*1*0.8125),0) -> 0 | I17: =IFERROR(((Returns!B6*1.1*0.8125)-Returns!B7)/(Returns!B6*1.1*0.8125),0) -> 0 | J17: =IFERROR(((Returns!B6*1.2*0.8125)-Returns!B7)/(Returns!B6*1.2*0.8125),0) -> 0 | K17: =IFERROR(((Returns!B6*1.3*0.8125)-Returns!B7)/(Returns!B6*1.3*0.8125),0) -> 0 | M17: ASP (RM psf) | N17: NDV adj (RM'000) | O17: GDC ex-land | P17: Target return | Q17: Max land cost (RM'000) | R17: Max land psf (RM) | S17: vs current land cost | T17: Viable?
D18: 80% absorption | E18: =IFERROR(((Returns!B6*0.7*1)-Returns!B7)/(Returns!B6*0.7*1),0) -> 0 | F18: =IFERROR(((Returns!B6*0.8*1)-Returns!B7)/(Returns!B6*0.8*1),0) -> 0 | G18: =IFERROR(((Returns!B6*0.9*1)-Returns!B7)/(Returns!B6*0.9*1),0) -> 0 | H18: =IFERROR(((Returns!B6*1*1)-Returns!B7)/(Returns!B6*1*1),0) -> 0 | I18: =IFERROR(((Returns!B6*1.1*1)-Returns!B7)/(Returns!B6*1.1*1),0) -> 0 | J18: =IFERROR(((Returns!B6*1.2*1)-Returns!B7)/(Returns!B6*1.2*1),0) -> 0 | K18: =IFERROR(((Returns!B6*1.3*1)-Returns!B7)/(Returns!B6*1.3*1),0) -> 0 | M18: RM 476 | N18: =(Returns!B6*0.7) -> #REF! | O18: =(Returns!B7-Cashflow!B15) -> #REF! | P18: =((Returns!B6*0.7)*0.25) -> #REF! | Q18: =MAX(0,(Returns!B6*0.7)-(Returns!B7-Cashflow!B15)-((Returns!B6*0.7)*0.25)) -> #REF! | R18: =IFERROR(MAX(0,(Returns!B6*0.7)-(Returns!B7-Cashflow!B15)-((Returns!B6*0.7)*0.25))*1000/('Feasibility Study'!#REF!*43560),0) -> 0 | S18: =IFERROR(MAX(0,(Returns!B6*0.7)-(Returns!B7-Cashflow!B15)-((Returns!B6*0.7)*0.25))/Cashflow!B15-1,0) -> 0 | T18: =IF(MAX(0,(Returns!B6*0.7)-(Returns!B7-Cashflow!B15)-((Returns!B6*0.7)*0.25))>=Cashflow!B15,"Yes ✓","No ✗") -> #REF!
A19: Dev margin % on NDV | B19: =IFERROR(Returns!B8/Returns!B6,0) -> 0 | D19: 95% absorption | E19: =IFERROR(((Returns!B6*0.7*1.1875)-Returns!B7)/(Returns!B6*0.7*1.1875),0) -> 0 | F19: =IFERROR(((Returns!B6*0.8*1.1875)-Returns!B7)/(Returns!B6*0.8*1.1875),0) -> 0 | G19: =IFERROR(((Returns!B6*0.9*1.1875)-Returns!B7)/(Returns!B6*0.9*1.1875),0) -> 0 | H19: =IFERROR(((Returns!B6*1*1.1875)-Returns!B7)/(Returns!B6*1*1.1875),0) -> 0 | I19: =IFERROR(((Returns!B6*1.1*1.1875)-Returns!B7)/(Returns!B6*1.1*1.1875),0) -> 0 | J19: =IFERROR(((Returns!B6*1.2*1.1875)-Returns!B7)/(Returns!B6*1.2*1.1875),0) -> 0 | K19: =IFERROR(((Returns!B6*1.3*1.1875)-Returns!B7)/(Returns!B6*1.3*1.1875),0) -> 0 | M19: RM 544 | N19: =(Returns!B6*0.8) -> #REF! | O19: =(Returns!B7-Cashflow!B15) -> #REF! | P19: =((Returns!B6*0.8)*0.25) -> #REF! | Q19: =MAX(0,(Returns!B6*0.8)-(Returns!B7-Cashflow!B15)-((Returns!B6*0.8)*0.25)) -> #REF! | R19: =IFERROR(MAX(0,(Returns!B6*0.8)-(Returns!B7-Cashflow!B15)-((Returns!B6*0.8)*0.25))*1000/('Feasibility Study'!#REF!*43560),0) -> 0 | S19: =IFERROR(MAX(0,(Returns!B6*0.8)-(Returns!B7-Cashflow!B15)-((Returns!B6*0.8)*0.25))/Cashflow!B15-1,0) -> 0 | T19: =IF(MAX(0,(Returns!B6*0.8)-(Returns!B7-Cashflow!B15)-((Returns!B6*0.8)*0.25))>=Cashflow!B15,"Yes ✓","No ✗") -> #REF!
A20: Dev margin % on GDV | B20: =IFERROR(Returns!B8/Returns!B5,0) -> 0 | D20: 110% absorption | E20: =IFERROR(((Returns!B6*0.7*1.375)-Returns!B7)/(Returns!B6*0.7*1.375),0) -> 0 | F20: =IFERROR(((Returns!B6*0.8*1.375)-Returns!B7)/(Returns!B6*0.8*1.375),0) -> 0 | G20: =IFERROR(((Returns!B6*0.9*1.375)-Returns!B7)/(Returns!B6*0.9*1.375),0) -> 0 | H20: =IFERROR(((Returns!B6*1*1.375)-Returns!B7)/(Returns!B6*1*1.375),0) -> 0 | I20: =IFERROR(((Returns!B6*1.1*1.375)-Returns!B7)/(Returns!B6*1.1*1.375),0) -> 0 | J20: =IFERROR(((Returns!B6*1.2*1.375)-Returns!B7)/(Returns!B6*1.2*1.375),0) -> 0 | K20: =IFERROR(((Returns!B6*1.3*1.375)-Returns!B7)/(Returns!B6*1.3*1.375),0) -> 0 | M20: RM 612 | N20: =(Returns!B6*0.9) -> #REF! | O20: =(Returns!B7-Cashflow!B15) -> #REF! | P20: =((Returns!B6*0.9)*0.25) -> #REF! | Q20: =MAX(0,(Returns!B6*0.9)-(Returns!B7-Cashflow!B15)-((Returns!B6*0.9)*0.25)) -> #REF! | R20: =IFERROR(MAX(0,(Returns!B6*0.9)-(Returns!B7-Cashflow!B15)-((Returns!B6*0.9)*0.25))*1000/('Feasibility Study'!#REF!*43560),0) -> 0 | S20: =IFERROR(MAX(0,(Returns!B6*0.9)-(Returns!B7-Cashflow!B15)-((Returns!B6*0.9)*0.25))/Cashflow!B15-1,0) -> 0 | T20: =IF(MAX(0,(Returns!B6*0.9)-(Returns!B7-Cashflow!B15)-((Returns!B6*0.9)*0.25))>=Cashflow!B15,"Yes ✓","No ✗") -> #REF!
A21: MOIC (NDP / peak equity) | B21: =IFERROR(Returns!B8/ABS(Returns!B12),0) -> 0 | M21: RM 680 | N21: =(Returns!B6*1) -> #REF! | O21: =(Returns!B7-Cashflow!B15) -> #REF! | P21: =((Returns!B6*1)*0.25) -> #REF! | Q21: =MAX(0,(Returns!B6*1)-(Returns!B7-Cashflow!B15)-((Returns!B6*1)*0.25)) -> #REF! | R21: =IFERROR(MAX(0,(Returns!B6*1)-(Returns!B7-Cashflow!B15)-((Returns!B6*1)*0.25))*1000/('Feasibility Study'!#REF!*43560),0) -> 0 | S21: =IFERROR(MAX(0,(Returns!B6*1)-(Returns!B7-Cashflow!B15)-((Returns!B6*1)*0.25))/Cashflow!B15-1,0) -> 0 | T21: =IF(MAX(0,(Returns!B6*1)-(Returns!B7-Cashflow!B15)-((Returns!B6*1)*0.25))>=Cashflow!B15,"Yes ✓","No ✗") -> #REF!
M22: RM 748 | N22: =(Returns!B6*1.1) -> #REF! | O22: =(Returns!B7-Cashflow!B15) -> #REF! | P22: =((Returns!B6*1.1)*0.25) -> #REF! | Q22: =MAX(0,(Returns!B6*1.1)-(Returns!B7-Cashflow!B15)-((Returns!B6*1.1)*0.25)) -> #REF! | R22: =IFERROR(MAX(0,(Returns!B6*1.1)-(Returns!B7-Cashflow!B15)-((Returns!B6*1.1)*0.25))*1000/('Feasibility Study'!#REF!*43560),0) -> 0 | S22: =IFERROR(MAX(0,(Returns!B6*1.1)-(Returns!B7-Cashflow!B15)-((Returns!B6*1.1)*0.25))/Cashflow!B15-1,0) -> 0 | T22: =IF(MAX(0,(Returns!B6*1.1)-(Returns!B7-Cashflow!B15)-((Returns!B6*1.1)*0.25))>=Cashflow!B15,"Yes ✓","No ✗") -> #REF!
A23: KEY & NOTES | M23: RM 816 | N23: =(Returns!B6*1.2) -> #REF! | O23: =(Returns!B7-Cashflow!B15) -> #REF! | P23: =((Returns!B6*1.2)*0.25) -> #REF! | Q23: =MAX(0,(Returns!B6*1.2)-(Returns!B7-Cashflow!B15)-((Returns!B6*1.2)*0.25)) -> #REF! | R23: =IFERROR(MAX(0,(Returns!B6*1.2)-(Returns!B7-Cashflow!B15)-((Returns!B6*1.2)*0.25))*1000/('Feasibility Study'!#REF!*43560),0) -> 0 | S23: =IFERROR(MAX(0,(Returns!B6*1.2)-(Returns!B7-Cashflow!B15)-((Returns!B6*1.2)*0.25))/Cashflow!B15-1,0) -> 0 | T23: =IF(MAX(0,(Returns!B6*1.2)-(Returns!B7-Cashflow!B15)-((Returns!B6*1.2)*0.25))>=Cashflow!B15,"Yes ✓","No ✗") -> #REF!
A24: Green cells | B24: IRR ≥ hurdle (Cashflow!B18) or NDP margin ≥ 25% | M24: RM 884 | N24: =(Returns!B6*1.3) -> #REF! | O24: =(Returns!B7-Cashflow!B15) -> #REF! | P24: =((Returns!B6*1.3)*0.25) -> #REF! | Q24: =MAX(0,(Returns!B6*1.3)-(Returns!B7-Cashflow!B15)-((Returns!B6*1.3)*0.25)) -> #REF! | R24: =IFERROR(MAX(0,(Returns!B6*1.3)-(Returns!B7-Cashflow!B15)-((Returns!B6*1.3)*0.25))*1000/('Feasibility Study'!#REF!*43560),0) -> 0 | S24: =IFERROR(MAX(0,(Returns!B6*1.3)-(Returns!B7-Cashflow!B15)-((Returns!B6*1.3)*0.25))/Cashflow!B15-1,0) -> 0 | T24: =IF(MAX(0,(Returns!B6*1.3)-(Returns!B7-Cashflow!B15)-((Returns!B6*1.3)*0.25))>=Cashflow!B15,"Yes ✓","No ✗") -> #REF!
A25: Red cells | B25: IRR < hurdle or NDP margin < 15%
A26: Amber cells | B26: NDP margin between 15–25%
A27: Yellow cell | B27: Base case (RM 680 psf ASP, 80% absorption)
A28: XIRR formula | B28: Monthly cash flows; dates auto-linked from Returns sheet rows 19–78
A29: IRR scaling | B29: Proportional to revenue (ASP × Abs); accurate within ±15% of base case
A30: Land breakeven | B30: Target dev margin = 25% of NDV; edit formula directly to change target
A31: Update model | B31: Fill unit counts & prices in Feasibility Study — all cells auto-update
A32: Total NDP — absolute return (RM'000) | B32: =Returns!B86 -> Inputs needed
